2024-10-20 20:32:12,415 - __main__ - INFO - 开始计算
2024-10-20 20:32:12,911 - __main__ - ERROR - excel_index: 5 | test_index: 0 | attempt_time: 0 problem failed！
2024-10-20 20:32:12,928 - __main__ - ERROR - excel_index: 2 | test_index: 0 | attempt_time: 0 problem failed！
2024-10-20 20:32:12,932 - __main__ - ERROR - excel_index: 4 | test_index: 0 | attempt_time: 0 problem failed！
2024-10-20 20:32:12,937 - __main__ - ERROR - excel_index: 9 | test_index: 0 | attempt_time: 0 problem failed！
2024-10-20 20:32:12,948 - __main__ - ERROR - excel_index: 7 | test_index: 0 | attempt_time: 0 problem failed！
2024-10-20 20:32:12,964 - __main__ - ERROR - excel_index: 0 | test_index: 0 | attempt_time: 0 problem failed！
2024-10-20 20:32:12,977 - __main__ - ERROR - excel_index: 10 | test_index: 1 | attempt_time: 0 problem failed！
2024-10-20 20:32:12,981 - __main__ - ERROR - excel_index: 3 | test_index: 0 | attempt_time: 0 problem failed！
2024-10-20 20:32:12,992 - __main__ - ERROR - excel_index: 13 | test_index: 1 | attempt_time: 0 problem failed！
2024-10-20 20:32:13,004 - __main__ - ERROR - excel_index: 8 | test_index: 0 | attempt_time: 0 problem failed！
2024-10-20 20:32:13,012 - __main__ - ERROR - excel_index: 6 | test_index: 0 | attempt_time: 0 problem failed！
2024-10-20 20:32:13,017 - __main__ - ERROR - excel_index: 11 | test_index: 1 | attempt_time: 0 problem failed！
2024-10-20 20:32:13,042 - __main__ - ERROR - excel_index: 19 | test_index: 1 | attempt_time: 0 problem failed！
2024-10-20 20:32:13,059 - __main__ - ERROR - excel_index: 12 | test_index: 1 | attempt_time: 0 problem failed！
2024-10-20 20:32:13,077 - __main__ - ERROR - excel_index: 16 | test_index: 1 | attempt_time: 0 problem failed！
2024-10-20 20:32:13,103 - __main__ - ERROR - excel_index: 22 | test_index: 2 | attempt_time: 0 problem failed！
2024-10-20 20:32:13,108 - __main__ - ERROR - excel_index: 24 | test_index: 2 | attempt_time: 0 problem failed！
2024-10-20 20:32:13,118 - __main__ - ERROR - excel_index: 20 | test_index: 2 | attempt_time: 0 problem failed！
2024-10-20 20:32:13,128 - __main__ - ERROR - excel_index: 21 | test_index: 2 | attempt_time: 0 problem failed！
2024-10-20 20:32:13,132 - __main__ - ERROR - excel_index: 29 | test_index: 2 | attempt_time: 0 problem failed！
2024-10-20 20:32:13,147 - __main__ - ERROR - excel_index: 28 | test_index: 2 | attempt_time: 0 problem failed！
2024-10-20 20:32:13,177 - __main__ - ERROR - excel_index: 27 | test_index: 2 | attempt_time: 0 problem failed！
2024-10-20 20:32:13,179 - __main__ - ERROR - excel_index: 23 | test_index: 2 | attempt_time: 0 problem failed！
2024-10-20 20:32:13,180 - __main__ - ERROR - excel_index: 26 | test_index: 2 | attempt_time: 0 problem failed！
2024-10-20 20:32:13,191 - __main__ - ERROR - excel_index: 25 | test_index: 2 | attempt_time: 0 problem failed！
2024-10-20 20:32:13,199 - __main__ - ERROR - excel_index: 15 | test_index: 1 | attempt_time: 0 problem failed！
2024-10-20 20:32:13,246 - __main__ - ERROR - excel_index: 44 | test_index: 4 | attempt_time: 0 problem failed！
2024-10-20 20:32:13,249 - __main__ - ERROR - excel_index: 34 | test_index: 3 | attempt_time: 0 problem failed！
2024-10-20 20:32:13,253 - __main__ - ERROR - excel_index: 17 | test_index: 1 | attempt_time: 0 problem failed！
2024-10-20 20:32:13,256 - __main__ - ERROR - excel_index: 37 | test_index: 3 | attempt_time: 0 problem failed！
2024-10-20 20:32:13,258 - __main__ - ERROR - excel_index: 1 | test_index: 0 | attempt_time: 0 problem failed！
2024-10-20 20:32:13,260 - __main__ - ERROR - excel_index: 14 | test_index: 1 | attempt_time: 0 problem failed！
2024-10-20 20:32:13,266 - __main__ - ERROR - excel_index: 35 | test_index: 3 | attempt_time: 0 problem failed！
2024-10-20 20:32:13,268 - __main__ - ERROR - excel_index: 38 | test_index: 3 | attempt_time: 0 problem failed！
2024-10-20 20:32:13,270 - __main__ - ERROR - excel_index: 39 | test_index: 3 | attempt_time: 0 problem failed！
2024-10-20 20:32:13,282 - __main__ - ERROR - excel_index: 33 | test_index: 3 | attempt_time: 0 problem failed！
2024-10-20 20:32:13,284 - __main__ - ERROR - excel_index: 45 | test_index: 4 | attempt_time: 0 problem failed！
2024-10-20 20:32:13,297 - __main__ - ERROR - excel_index: 40 | test_index: 4 | attempt_time: 0 problem failed！
2024-10-20 20:32:13,309 - __main__ - ERROR - excel_index: 41 | test_index: 4 | attempt_time: 0 problem failed！
2024-10-20 20:32:13,312 - __main__ - ERROR - excel_index: 31 | test_index: 3 | attempt_time: 0 problem failed！
2024-10-20 20:32:13,314 - __main__ - ERROR - excel_index: 32 | test_index: 3 | attempt_time: 0 problem failed！
2024-10-20 20:32:13,316 - __main__ - ERROR - excel_index: 49 | test_index: 4 | attempt_time: 0 problem failed！
2024-10-20 20:32:13,332 - __main__ - ERROR - excel_index: 47 | test_index: 4 | attempt_time: 0 problem failed！
2024-10-20 20:32:13,340 - __main__ - ERROR - excel_index: 30 | test_index: 3 | attempt_time: 0 problem failed！
2024-10-20 20:32:13,342 - __main__ - ERROR - excel_index: 48 | test_index: 4 | attempt_time: 0 problem failed！
2024-10-20 20:32:13,362 - __main__ - ERROR - excel_index: 36 | test_index: 3 | attempt_time: 0 problem failed！
2024-10-20 20:32:13,368 - __main__ - ERROR - excel_index: 43 | test_index: 4 | attempt_time: 0 problem failed！
2024-10-20 20:32:13,710 - __main__ - ERROR - excel_index: 42 | test_index: 4 | attempt_time: 0 problem failed！
2024-10-20 20:32:13,879 - __main__ - ERROR - excel_index: 46 | test_index: 4 | attempt_time: 0 problem failed！
2024-10-20 20:32:16,559 - __main__ - ERROR - excel_index: 18 | test_index: 1 | attempt_time: 0 problem failed！
2024-10-20 20:32:18,267 - __main__ - ERROR - excel_index: 5 | test_index: 0 | attempt_time: 1 problem failed！
2024-10-20 20:32:18,322 - __main__ - ERROR - excel_index: 9 | test_index: 0 | attempt_time: 1 problem failed！
2024-10-20 20:32:18,343 - __main__ - ERROR - excel_index: 0 | test_index: 0 | attempt_time: 1 problem failed！
2024-10-20 20:32:18,354 - __main__ - ERROR - excel_index: 7 | test_index: 0 | attempt_time: 1 problem failed！
2024-10-20 20:32:18,363 - __main__ - ERROR - excel_index: 2 | test_index: 0 | attempt_time: 1 problem failed！
2024-10-20 20:32:18,387 - __main__ - ERROR - excel_index: 4 | test_index: 0 | attempt_time: 1 problem failed！
2024-10-20 20:32:18,408 - __main__ - ERROR - excel_index: 6 | test_index: 0 | attempt_time: 1 problem failed！
2024-10-20 20:32:18,443 - __main__ - ERROR - excel_index: 10 | test_index: 1 | attempt_time: 1 problem failed！
2024-10-20 20:32:18,452 - __main__ - ERROR - excel_index: 8 | test_index: 0 | attempt_time: 1 problem failed！
2024-10-20 20:32:18,519 - __main__ - ERROR - excel_index: 12 | test_index: 1 | attempt_time: 1 problem failed！
2024-10-20 20:32:18,527 - __main__ - ERROR - excel_index: 3 | test_index: 0 | attempt_time: 1 problem failed！
2024-10-20 20:32:18,557 - __main__ - ERROR - excel_index: 19 | test_index: 1 | attempt_time: 1 problem failed！
2024-10-20 20:32:18,604 - __main__ - ERROR - excel_index: 16 | test_index: 1 | attempt_time: 1 problem failed！
2024-10-20 20:32:18,622 - __main__ - ERROR - excel_index: 11 | test_index: 1 | attempt_time: 1 problem failed！
2024-10-20 20:32:18,641 - __main__ - ERROR - excel_index: 13 | test_index: 1 | attempt_time: 1 problem failed！
2024-10-20 20:32:18,684 - __main__ - ERROR - excel_index: 29 | test_index: 2 | attempt_time: 1 problem failed！
2024-10-20 20:32:18,685 - __main__ - ERROR - excel_index: 21 | test_index: 2 | attempt_time: 1 problem failed！
2024-10-20 20:32:18,692 - __main__ - ERROR - excel_index: 15 | test_index: 1 | attempt_time: 1 problem failed！
2024-10-20 20:32:18,722 - __main__ - ERROR - excel_index: 24 | test_index: 2 | attempt_time: 1 problem failed！
2024-10-20 20:32:18,774 - __main__ - ERROR - excel_index: 28 | test_index: 2 | attempt_time: 1 problem failed！
2024-10-20 20:32:18,777 - __main__ - ERROR - excel_index: 14 | test_index: 1 | attempt_time: 1 problem failed！
2024-10-20 20:32:18,789 - __main__ - ERROR - excel_index: 1 | test_index: 0 | attempt_time: 1 problem failed！
2024-10-20 20:32:18,790 - __main__ - ERROR - excel_index: 27 | test_index: 2 | attempt_time: 1 problem failed！
2024-10-20 20:32:18,804 - __main__ - ERROR - excel_index: 25 | test_index: 2 | attempt_time: 1 problem failed！
2024-10-20 20:32:18,813 - __main__ - ERROR - excel_index: 26 | test_index: 2 | attempt_time: 1 problem failed！
2024-10-20 20:32:18,855 - __main__ - ERROR - excel_index: 17 | test_index: 1 | attempt_time: 1 problem failed！
2024-10-20 20:32:18,888 - __main__ - ERROR - excel_index: 34 | test_index: 3 | attempt_time: 1 problem failed！
2024-10-20 20:32:18,901 - __main__ - ERROR - excel_index: 22 | test_index: 2 | attempt_time: 1 problem failed！
2024-10-20 20:32:18,994 - __main__ - ERROR - excel_index: 44 | test_index: 4 | attempt_time: 1 problem failed！
2024-10-20 20:32:19,004 - __main__ - ERROR - excel_index: 40 | test_index: 4 | attempt_time: 1 problem failed！
2024-10-20 20:32:19,026 - __main__ - ERROR - excel_index: 39 | test_index: 3 | attempt_time: 1 problem failed！
2024-10-20 20:32:19,032 - __main__ - ERROR - excel_index: 32 | test_index: 3 | attempt_time: 1 problem failed！
2024-10-20 20:32:19,053 - __main__ - ERROR - excel_index: 30 | test_index: 3 | attempt_time: 1 problem failed！
2024-10-20 20:32:19,060 - __main__ - ERROR - excel_index: 33 | test_index: 3 | attempt_time: 1 problem failed！
2024-10-20 20:32:19,085 - __main__ - ERROR - excel_index: 35 | test_index: 3 | attempt_time: 1 problem failed！
2024-10-20 20:32:19,123 - __main__ - ERROR - excel_index: 49 | test_index: 4 | attempt_time: 1 problem failed！
2024-10-20 20:32:19,133 - __main__ - ERROR - excel_index: 48 | test_index: 4 | attempt_time: 1 problem failed！
2024-10-20 20:32:19,160 - __main__ - ERROR - excel_index: 47 | test_index: 4 | attempt_time: 1 problem failed！
2024-10-20 20:32:19,216 - __main__ - ERROR - excel_index: 37 | test_index: 3 | attempt_time: 1 problem failed！
2024-10-20 20:32:19,239 - __main__ - ERROR - excel_index: 38 | test_index: 3 | attempt_time: 1 problem failed！
2024-10-20 20:32:19,246 - __main__ - ERROR - excel_index: 41 | test_index: 4 | attempt_time: 1 problem failed！
2024-10-20 20:32:19,307 - __main__ - ERROR - excel_index: 43 | test_index: 4 | attempt_time: 1 problem failed！
2024-10-20 20:32:19,493 - __main__ - ERROR - excel_index: 42 | test_index: 4 | attempt_time: 1 problem failed！
2024-10-20 20:32:19,495 - __main__ - ERROR - excel_index: 20 | test_index: 2 | attempt_time: 1 problem failed！
2024-10-20 20:32:19,586 - __main__ - ERROR - excel_index: 45 | test_index: 4 | attempt_time: 1 problem failed！
2024-10-20 20:32:19,591 - __main__ - ERROR - excel_index: 46 | test_index: 4 | attempt_time: 1 problem failed！
2024-10-20 20:32:20,103 - __main__ - ERROR - excel_index: 23 | test_index: 2 | attempt_time: 1 problem failed！
2024-10-20 20:32:20,578 - __main__ - ERROR - excel_index: 31 | test_index: 3 | attempt_time: 1 problem failed！
2024-10-20 20:32:20,708 - __main__ - ERROR - excel_index: 36 | test_index: 3 | attempt_time: 1 problem failed！
2024-10-20 20:32:22,192 - __main__ - ERROR - excel_index: 18 | test_index: 1 | attempt_time: 1 problem failed！
2024-10-20 20:32:23,671 - __main__ - ERROR - excel_index: 5 | test_index: 0 | attempt_time: 2 problem failed！
======================== wrong message ========================: 
[Errno 13] Permission denied: 'tmp\\data.xlsx'
======================== trace back ========================: 
Traceback (most recent call last):
  File "C:\Users\Admin\PycharmProjects\ByteProject\doubao\origin\v2\parallel\parallel_test.py", line 162, in request
    write_excel(excel_content)
  File "C:\Users\Admin\PycharmProjects\ByteProject\doubao\origin\v2\parallel\parallel_test.py", line 265, in write_excel
    CONSTANTS.excel_info["workbook"].save(CONSTANTS.excel_info["excel_path"])
  File "C:\Users\Admin\PycharmProjects\ByteProject\venv\Lib\site-packages\openpyxl\workbook\workbook.py", line 386, in save
    save_workbook(self, filename)
  File "C:\Users\Admin\PycharmProjects\ByteProject\venv\Lib\site-packages\openpyxl\writer\excel.py", line 291, in save_workbook
    archive = ZipFile(filename, 'w', ZIP_DEFLATED, allowZip64=True)
              ^^^^^^^^^^^^^^^^^^^^^^^^^^^^^^^^^^^^^^^^^^^^^^^^^^^^^
  File "C:\Program Files\WindowsApps\PythonSoftwareFoundation.Python.3.12_3.12.2032.0_x64__qbz5n2kfra8p0\Lib\zipfile\__init__.py", line 1331, in __init__
    self.fp = io.open(file, filemode)
              ^^^^^^^^^^^^^^^^^^^^^^^
PermissionError: [Errno 13] Permission denied: 'tmp\\data.xlsx'
======================== content ========================: 
ABC123
2024-10-20 20:32:23,717 - __main__ - ERROR - excel_index: 9 | test_index: 0 | attempt_time: 2 problem failed！
======================== wrong message ========================: 
[Errno 13] Permission denied: 'tmp\\data.xlsx'
======================== trace back ========================: 
Traceback (most recent call last):
  File "C:\Users\Admin\PycharmProjects\ByteProject\doubao\origin\v2\parallel\parallel_test.py", line 162, in request
    write_excel(excel_content)
  File "C:\Users\Admin\PycharmProjects\ByteProject\doubao\origin\v2\parallel\parallel_test.py", line 265, in write_excel
    CONSTANTS.excel_info["workbook"].save(CONSTANTS.excel_info["excel_path"])
  File "C:\Users\Admin\PycharmProjects\ByteProject\venv\Lib\site-packages\openpyxl\workbook\workbook.py", line 386, in save
    save_workbook(self, filename)
  File "C:\Users\Admin\PycharmProjects\ByteProject\venv\Lib\site-packages\openpyxl\writer\excel.py", line 291, in save_workbook
    archive = ZipFile(filename, 'w', ZIP_DEFLATED, allowZip64=True)
              ^^^^^^^^^^^^^^^^^^^^^^^^^^^^^^^^^^^^^^^^^^^^^^^^^^^^^
  File "C:\Program Files\WindowsApps\PythonSoftwareFoundation.Python.3.12_3.12.2032.0_x64__qbz5n2kfra8p0\Lib\zipfile\__init__.py", line 1331, in __init__
    self.fp = io.open(file, filemode)
              ^^^^^^^^^^^^^^^^^^^^^^^
PermissionError: [Errno 13] Permission denied: 'tmp\\data.xlsx'
======================== content ========================: 
ABC123
2024-10-20 20:32:23,758 - __main__ - ERROR - excel_index: 2 | test_index: 0 | attempt_time: 2 problem failed！
======================== wrong message ========================: 
[Errno 13] Permission denied: 'tmp\\data.xlsx'
======================== trace back ========================: 
Traceback (most recent call last):
  File "C:\Users\Admin\PycharmProjects\ByteProject\doubao\origin\v2\parallel\parallel_test.py", line 162, in request
    write_excel(excel_content)
  File "C:\Users\Admin\PycharmProjects\ByteProject\doubao\origin\v2\parallel\parallel_test.py", line 265, in write_excel
    CONSTANTS.excel_info["workbook"].save(CONSTANTS.excel_info["excel_path"])
  File "C:\Users\Admin\PycharmProjects\ByteProject\venv\Lib\site-packages\openpyxl\workbook\workbook.py", line 386, in save
    save_workbook(self, filename)
  File "C:\Users\Admin\PycharmProjects\ByteProject\venv\Lib\site-packages\openpyxl\writer\excel.py", line 291, in save_workbook
    archive = ZipFile(filename, 'w', ZIP_DEFLATED, allowZip64=True)
              ^^^^^^^^^^^^^^^^^^^^^^^^^^^^^^^^^^^^^^^^^^^^^^^^^^^^^
  File "C:\Program Files\WindowsApps\PythonSoftwareFoundation.Python.3.12_3.12.2032.0_x64__qbz5n2kfra8p0\Lib\zipfile\__init__.py", line 1331, in __init__
    self.fp = io.open(file, filemode)
              ^^^^^^^^^^^^^^^^^^^^^^^
PermissionError: [Errno 13] Permission denied: 'tmp\\data.xlsx'
======================== content ========================: 
ABC123
2024-10-20 20:32:23,765 - __main__ - ERROR - excel_index: 0 | test_index: 0 | attempt_time: 2 problem failed！
======================== wrong message ========================: 
[Errno 13] Permission denied: 'tmp\\data.xlsx'
======================== trace back ========================: 
Traceback (most recent call last):
  File "C:\Users\Admin\PycharmProjects\ByteProject\doubao\origin\v2\parallel\parallel_test.py", line 162, in request
    write_excel(excel_content)
  File "C:\Users\Admin\PycharmProjects\ByteProject\doubao\origin\v2\parallel\parallel_test.py", line 265, in write_excel
    CONSTANTS.excel_info["workbook"].save(CONSTANTS.excel_info["excel_path"])
  File "C:\Users\Admin\PycharmProjects\ByteProject\venv\Lib\site-packages\openpyxl\workbook\workbook.py", line 386, in save
    save_workbook(self, filename)
  File "C:\Users\Admin\PycharmProjects\ByteProject\venv\Lib\site-packages\openpyxl\writer\excel.py", line 291, in save_workbook
    archive = ZipFile(filename, 'w', ZIP_DEFLATED, allowZip64=True)
              ^^^^^^^^^^^^^^^^^^^^^^^^^^^^^^^^^^^^^^^^^^^^^^^^^^^^^
  File "C:\Program Files\WindowsApps\PythonSoftwareFoundation.Python.3.12_3.12.2032.0_x64__qbz5n2kfra8p0\Lib\zipfile\__init__.py", line 1331, in __init__
    self.fp = io.open(file, filemode)
              ^^^^^^^^^^^^^^^^^^^^^^^
PermissionError: [Errno 13] Permission denied: 'tmp\\data.xlsx'
======================== content ========================: 
ABC123
2024-10-20 20:32:23,847 - __main__ - ERROR - excel_index: 6 | test_index: 0 | attempt_time: 2 problem failed！
======================== wrong message ========================: 
[Errno 13] Permission denied: 'tmp\\data.xlsx'
======================== trace back ========================: 
Traceback (most recent call last):
  File "C:\Users\Admin\PycharmProjects\ByteProject\doubao\origin\v2\parallel\parallel_test.py", line 162, in request
    write_excel(excel_content)
  File "C:\Users\Admin\PycharmProjects\ByteProject\doubao\origin\v2\parallel\parallel_test.py", line 265, in write_excel
    CONSTANTS.excel_info["workbook"].save(CONSTANTS.excel_info["excel_path"])
  File "C:\Users\Admin\PycharmProjects\ByteProject\venv\Lib\site-packages\openpyxl\workbook\workbook.py", line 386, in save
    save_workbook(self, filename)
  File "C:\Users\Admin\PycharmProjects\ByteProject\venv\Lib\site-packages\openpyxl\writer\excel.py", line 291, in save_workbook
    archive = ZipFile(filename, 'w', ZIP_DEFLATED, allowZip64=True)
              ^^^^^^^^^^^^^^^^^^^^^^^^^^^^^^^^^^^^^^^^^^^^^^^^^^^^^
  File "C:\Program Files\WindowsApps\PythonSoftwareFoundation.Python.3.12_3.12.2032.0_x64__qbz5n2kfra8p0\Lib\zipfile\__init__.py", line 1331, in __init__
    self.fp = io.open(file, filemode)
              ^^^^^^^^^^^^^^^^^^^^^^^
PermissionError: [Errno 13] Permission denied: 'tmp\\data.xlsx'
======================== content ========================: 
ABC123
2024-10-20 20:32:23,848 - __main__ - ERROR - excel_index: 8 | test_index: 0 | attempt_time: 2 problem failed！
======================== wrong message ========================: 
[Errno 13] Permission denied: 'tmp\\data.xlsx'
======================== trace back ========================: 
Traceback (most recent call last):
  File "C:\Users\Admin\PycharmProjects\ByteProject\doubao\origin\v2\parallel\parallel_test.py", line 162, in request
    write_excel(excel_content)
  File "C:\Users\Admin\PycharmProjects\ByteProject\doubao\origin\v2\parallel\parallel_test.py", line 265, in write_excel
    CONSTANTS.excel_info["workbook"].save(CONSTANTS.excel_info["excel_path"])
  File "C:\Users\Admin\PycharmProjects\ByteProject\venv\Lib\site-packages\openpyxl\workbook\workbook.py", line 386, in save
    save_workbook(self, filename)
  File "C:\Users\Admin\PycharmProjects\ByteProject\venv\Lib\site-packages\openpyxl\writer\excel.py", line 291, in save_workbook
    archive = ZipFile(filename, 'w', ZIP_DEFLATED, allowZip64=True)
              ^^^^^^^^^^^^^^^^^^^^^^^^^^^^^^^^^^^^^^^^^^^^^^^^^^^^^
  File "C:\Program Files\WindowsApps\PythonSoftwareFoundation.Python.3.12_3.12.2032.0_x64__qbz5n2kfra8p0\Lib\zipfile\__init__.py", line 1331, in __init__
    self.fp = io.open(file, filemode)
              ^^^^^^^^^^^^^^^^^^^^^^^
PermissionError: [Errno 13] Permission denied: 'tmp\\data.xlsx'
======================== content ========================: 
ABC123
2024-10-20 20:32:23,850 - __main__ - ERROR - excel_index: 4 | test_index: 0 | attempt_time: 2 problem failed！
======================== wrong message ========================: 
[Errno 13] Permission denied: 'tmp\\data.xlsx'
======================== trace back ========================: 
Traceback (most recent call last):
  File "C:\Users\Admin\PycharmProjects\ByteProject\doubao\origin\v2\parallel\parallel_test.py", line 162, in request
    write_excel(excel_content)
  File "C:\Users\Admin\PycharmProjects\ByteProject\doubao\origin\v2\parallel\parallel_test.py", line 265, in write_excel
    CONSTANTS.excel_info["workbook"].save(CONSTANTS.excel_info["excel_path"])
  File "C:\Users\Admin\PycharmProjects\ByteProject\venv\Lib\site-packages\openpyxl\workbook\workbook.py", line 386, in save
    save_workbook(self, filename)
  File "C:\Users\Admin\PycharmProjects\ByteProject\venv\Lib\site-packages\openpyxl\writer\excel.py", line 291, in save_workbook
    archive = ZipFile(filename, 'w', ZIP_DEFLATED, allowZip64=True)
              ^^^^^^^^^^^^^^^^^^^^^^^^^^^^^^^^^^^^^^^^^^^^^^^^^^^^^
  File "C:\Program Files\WindowsApps\PythonSoftwareFoundation.Python.3.12_3.12.2032.0_x64__qbz5n2kfra8p0\Lib\zipfile\__init__.py", line 1331, in __init__
    self.fp = io.open(file, filemode)
              ^^^^^^^^^^^^^^^^^^^^^^^
PermissionError: [Errno 13] Permission denied: 'tmp\\data.xlsx'
======================== content ========================: 
ABC123
2024-10-20 20:32:23,906 - __main__ - ERROR - excel_index: 3 | test_index: 0 | attempt_time: 2 problem failed！
======================== wrong message ========================: 
[Errno 13] Permission denied: 'tmp\\data.xlsx'
======================== trace back ========================: 
Traceback (most recent call last):
  File "C:\Users\Admin\PycharmProjects\ByteProject\doubao\origin\v2\parallel\parallel_test.py", line 162, in request
    write_excel(excel_content)
  File "C:\Users\Admin\PycharmProjects\ByteProject\doubao\origin\v2\parallel\parallel_test.py", line 265, in write_excel
    CONSTANTS.excel_info["workbook"].save(CONSTANTS.excel_info["excel_path"])
  File "C:\Users\Admin\PycharmProjects\ByteProject\venv\Lib\site-packages\openpyxl\workbook\workbook.py", line 386, in save
    save_workbook(self, filename)
  File "C:\Users\Admin\PycharmProjects\ByteProject\venv\Lib\site-packages\openpyxl\writer\excel.py", line 291, in save_workbook
    archive = ZipFile(filename, 'w', ZIP_DEFLATED, allowZip64=True)
              ^^^^^^^^^^^^^^^^^^^^^^^^^^^^^^^^^^^^^^^^^^^^^^^^^^^^^
  File "C:\Program Files\WindowsApps\PythonSoftwareFoundation.Python.3.12_3.12.2032.0_x64__qbz5n2kfra8p0\Lib\zipfile\__init__.py", line 1331, in __init__
    self.fp = io.open(file, filemode)
              ^^^^^^^^^^^^^^^^^^^^^^^
PermissionError: [Errno 13] Permission denied: 'tmp\\data.xlsx'
======================== content ========================: 
ABC123
2024-10-20 20:32:24,048 - __main__ - ERROR - excel_index: 19 | test_index: 1 | attempt_time: 2 problem failed！
======================== wrong message ========================: 
[Errno 13] Permission denied: 'tmp\\data.xlsx'
======================== trace back ========================: 
Traceback (most recent call last):
  File "C:\Users\Admin\PycharmProjects\ByteProject\doubao\origin\v2\parallel\parallel_test.py", line 162, in request
    write_excel(excel_content)
  File "C:\Users\Admin\PycharmProjects\ByteProject\doubao\origin\v2\parallel\parallel_test.py", line 265, in write_excel
    CONSTANTS.excel_info["workbook"].save(CONSTANTS.excel_info["excel_path"])
  File "C:\Users\Admin\PycharmProjects\ByteProject\venv\Lib\site-packages\openpyxl\workbook\workbook.py", line 386, in save
    save_workbook(self, filename)
  File "C:\Users\Admin\PycharmProjects\ByteProject\venv\Lib\site-packages\openpyxl\writer\excel.py", line 291, in save_workbook
    archive = ZipFile(filename, 'w', ZIP_DEFLATED, allowZip64=True)
              ^^^^^^^^^^^^^^^^^^^^^^^^^^^^^^^^^^^^^^^^^^^^^^^^^^^^^
  File "C:\Program Files\WindowsApps\PythonSoftwareFoundation.Python.3.12_3.12.2032.0_x64__qbz5n2kfra8p0\Lib\zipfile\__init__.py", line 1331, in __init__
    self.fp = io.open(file, filemode)
              ^^^^^^^^^^^^^^^^^^^^^^^
PermissionError: [Errno 13] Permission denied: 'tmp\\data.xlsx'
======================== content ========================: 
ABC123qwer
2024-10-20 20:32:24,117 - __main__ - ERROR - excel_index: 16 | test_index: 1 | attempt_time: 2 problem failed！
======================== wrong message ========================: 
[Errno 13] Permission denied: 'tmp\\data.xlsx'
======================== trace back ========================: 
Traceback (most recent call last):
  File "C:\Users\Admin\PycharmProjects\ByteProject\doubao\origin\v2\parallel\parallel_test.py", line 162, in request
    write_excel(excel_content)
  File "C:\Users\Admin\PycharmProjects\ByteProject\doubao\origin\v2\parallel\parallel_test.py", line 265, in write_excel
    CONSTANTS.excel_info["workbook"].save(CONSTANTS.excel_info["excel_path"])
  File "C:\Users\Admin\PycharmProjects\ByteProject\venv\Lib\site-packages\openpyxl\workbook\workbook.py", line 386, in save
    save_workbook(self, filename)
  File "C:\Users\Admin\PycharmProjects\ByteProject\venv\Lib\site-packages\openpyxl\writer\excel.py", line 291, in save_workbook
    archive = ZipFile(filename, 'w', ZIP_DEFLATED, allowZip64=True)
              ^^^^^^^^^^^^^^^^^^^^^^^^^^^^^^^^^^^^^^^^^^^^^^^^^^^^^
  File "C:\Program Files\WindowsApps\PythonSoftwareFoundation.Python.3.12_3.12.2032.0_x64__qbz5n2kfra8p0\Lib\zipfile\__init__.py", line 1331, in __init__
    self.fp = io.open(file, filemode)
              ^^^^^^^^^^^^^^^^^^^^^^^
PermissionError: [Errno 13] Permission denied: 'tmp\\data.xlsx'
======================== content ========================: 
ABC123qwer
2024-10-20 20:32:24,133 - __main__ - ERROR - excel_index: 13 | test_index: 1 | attempt_time: 2 problem failed！
======================== wrong message ========================: 
[Errno 13] Permission denied: 'tmp\\data.xlsx'
======================== trace back ========================: 
Traceback (most recent call last):
  File "C:\Users\Admin\PycharmProjects\ByteProject\doubao\origin\v2\parallel\parallel_test.py", line 162, in request
    write_excel(excel_content)
  File "C:\Users\Admin\PycharmProjects\ByteProject\doubao\origin\v2\parallel\parallel_test.py", line 265, in write_excel
    CONSTANTS.excel_info["workbook"].save(CONSTANTS.excel_info["excel_path"])
  File "C:\Users\Admin\PycharmProjects\ByteProject\venv\Lib\site-packages\openpyxl\workbook\workbook.py", line 386, in save
    save_workbook(self, filename)
  File "C:\Users\Admin\PycharmProjects\ByteProject\venv\Lib\site-packages\openpyxl\writer\excel.py", line 291, in save_workbook
    archive = ZipFile(filename, 'w', ZIP_DEFLATED, allowZip64=True)
              ^^^^^^^^^^^^^^^^^^^^^^^^^^^^^^^^^^^^^^^^^^^^^^^^^^^^^
  File "C:\Program Files\WindowsApps\PythonSoftwareFoundation.Python.3.12_3.12.2032.0_x64__qbz5n2kfra8p0\Lib\zipfile\__init__.py", line 1331, in __init__
    self.fp = io.open(file, filemode)
              ^^^^^^^^^^^^^^^^^^^^^^^
PermissionError: [Errno 13] Permission denied: 'tmp\\data.xlsx'
======================== content ========================: 
ABC123qwer
2024-10-20 20:32:24,194 - __main__ - ERROR - excel_index: 11 | test_index: 1 | attempt_time: 2 problem failed！
======================== wrong message ========================: 
[Errno 13] Permission denied: 'tmp\\data.xlsx'
======================== trace back ========================: 
Traceback (most recent call last):
  File "C:\Users\Admin\PycharmProjects\ByteProject\doubao\origin\v2\parallel\parallel_test.py", line 162, in request
    write_excel(excel_content)
  File "C:\Users\Admin\PycharmProjects\ByteProject\doubao\origin\v2\parallel\parallel_test.py", line 265, in write_excel
    CONSTANTS.excel_info["workbook"].save(CONSTANTS.excel_info["excel_path"])
  File "C:\Users\Admin\PycharmProjects\ByteProject\venv\Lib\site-packages\openpyxl\workbook\workbook.py", line 386, in save
    save_workbook(self, filename)
  File "C:\Users\Admin\PycharmProjects\ByteProject\venv\Lib\site-packages\openpyxl\writer\excel.py", line 291, in save_workbook
    archive = ZipFile(filename, 'w', ZIP_DEFLATED, allowZip64=True)
              ^^^^^^^^^^^^^^^^^^^^^^^^^^^^^^^^^^^^^^^^^^^^^^^^^^^^^
  File "C:\Program Files\WindowsApps\PythonSoftwareFoundation.Python.3.12_3.12.2032.0_x64__qbz5n2kfra8p0\Lib\zipfile\__init__.py", line 1331, in __init__
    self.fp = io.open(file, filemode)
              ^^^^^^^^^^^^^^^^^^^^^^^
PermissionError: [Errno 13] Permission denied: 'tmp\\data.xlsx'
======================== content ========================: 
ABC123qwer
2024-10-20 20:32:24,263 - __main__ - ERROR - excel_index: 1 | test_index: 0 | attempt_time: 2 problem failed！
======================== wrong message ========================: 
[Errno 13] Permission denied: 'tmp\\data.xlsx'
======================== trace back ========================: 
Traceback (most recent call last):
  File "C:\Users\Admin\PycharmProjects\ByteProject\doubao\origin\v2\parallel\parallel_test.py", line 162, in request
    write_excel(excel_content)
  File "C:\Users\Admin\PycharmProjects\ByteProject\doubao\origin\v2\parallel\parallel_test.py", line 265, in write_excel
    CONSTANTS.excel_info["workbook"].save(CONSTANTS.excel_info["excel_path"])
  File "C:\Users\Admin\PycharmProjects\ByteProject\venv\Lib\site-packages\openpyxl\workbook\workbook.py", line 386, in save
    save_workbook(self, filename)
  File "C:\Users\Admin\PycharmProjects\ByteProject\venv\Lib\site-packages\openpyxl\writer\excel.py", line 291, in save_workbook
    archive = ZipFile(filename, 'w', ZIP_DEFLATED, allowZip64=True)
              ^^^^^^^^^^^^^^^^^^^^^^^^^^^^^^^^^^^^^^^^^^^^^^^^^^^^^
  File "C:\Program Files\WindowsApps\PythonSoftwareFoundation.Python.3.12_3.12.2032.0_x64__qbz5n2kfra8p0\Lib\zipfile\__init__.py", line 1331, in __init__
    self.fp = io.open(file, filemode)
              ^^^^^^^^^^^^^^^^^^^^^^^
PermissionError: [Errno 13] Permission denied: 'tmp\\data.xlsx'
======================== content ========================: 
ABC123
2024-10-20 20:32:24,306 - __main__ - ERROR - excel_index: 24 | test_index: 2 | attempt_time: 2 problem failed！
======================== wrong message ========================: 
[Errno 13] Permission denied: 'tmp\\data.xlsx'
======================== trace back ========================: 
Traceback (most recent call last):
  File "C:\Users\Admin\PycharmProjects\ByteProject\doubao\origin\v2\parallel\parallel_test.py", line 162, in request
    write_excel(excel_content)
  File "C:\Users\Admin\PycharmProjects\ByteProject\doubao\origin\v2\parallel\parallel_test.py", line 265, in write_excel
    CONSTANTS.excel_info["workbook"].save(CONSTANTS.excel_info["excel_path"])
  File "C:\Users\Admin\PycharmProjects\ByteProject\venv\Lib\site-packages\openpyxl\workbook\workbook.py", line 386, in save
    save_workbook(self, filename)
  File "C:\Users\Admin\PycharmProjects\ByteProject\venv\Lib\site-packages\openpyxl\writer\excel.py", line 291, in save_workbook
    archive = ZipFile(filename, 'w', ZIP_DEFLATED, allowZip64=True)
              ^^^^^^^^^^^^^^^^^^^^^^^^^^^^^^^^^^^^^^^^^^^^^^^^^^^^^
  File "C:\Program Files\WindowsApps\PythonSoftwareFoundation.Python.3.12_3.12.2032.0_x64__qbz5n2kfra8p0\Lib\zipfile\__init__.py", line 1331, in __init__
    self.fp = io.open(file, filemode)
              ^^^^^^^^^^^^^^^^^^^^^^^
PermissionError: [Errno 13] Permission denied: 'tmp\\data.xlsx'
======================== content ========================: 
ABC123qwertyui
2024-10-20 20:32:24,311 - __main__ - ERROR - excel_index: 14 | test_index: 1 | attempt_time: 2 problem failed！
======================== wrong message ========================: 
[Errno 13] Permission denied: 'tmp\\data.xlsx'
======================== trace back ========================: 
Traceback (most recent call last):
  File "C:\Users\Admin\PycharmProjects\ByteProject\doubao\origin\v2\parallel\parallel_test.py", line 162, in request
    write_excel(excel_content)
  File "C:\Users\Admin\PycharmProjects\ByteProject\doubao\origin\v2\parallel\parallel_test.py", line 265, in write_excel
    CONSTANTS.excel_info["workbook"].save(CONSTANTS.excel_info["excel_path"])
  File "C:\Users\Admin\PycharmProjects\ByteProject\venv\Lib\site-packages\openpyxl\workbook\workbook.py", line 386, in save
    save_workbook(self, filename)
  File "C:\Users\Admin\PycharmProjects\ByteProject\venv\Lib\site-packages\openpyxl\writer\excel.py", line 291, in save_workbook
    archive = ZipFile(filename, 'w', ZIP_DEFLATED, allowZip64=True)
              ^^^^^^^^^^^^^^^^^^^^^^^^^^^^^^^^^^^^^^^^^^^^^^^^^^^^^
  File "C:\Program Files\WindowsApps\PythonSoftwareFoundation.Python.3.12_3.12.2032.0_x64__qbz5n2kfra8p0\Lib\zipfile\__init__.py", line 1331, in __init__
    self.fp = io.open(file, filemode)
              ^^^^^^^^^^^^^^^^^^^^^^^
PermissionError: [Errno 13] Permission denied: 'tmp\\data.xlsx'
======================== content ========================: 
ABC123qwer
2024-10-20 20:32:24,364 - __main__ - ERROR - excel_index: 25 | test_index: 2 | attempt_time: 2 problem failed！
======================== wrong message ========================: 
[Errno 13] Permission denied: 'tmp\\data.xlsx'
======================== trace back ========================: 
Traceback (most recent call last):
  File "C:\Users\Admin\PycharmProjects\ByteProject\doubao\origin\v2\parallel\parallel_test.py", line 162, in request
    write_excel(excel_content)
  File "C:\Users\Admin\PycharmProjects\ByteProject\doubao\origin\v2\parallel\parallel_test.py", line 265, in write_excel
    CONSTANTS.excel_info["workbook"].save(CONSTANTS.excel_info["excel_path"])
  File "C:\Users\Admin\PycharmProjects\ByteProject\venv\Lib\site-packages\openpyxl\workbook\workbook.py", line 386, in save
    save_workbook(self, filename)
  File "C:\Users\Admin\PycharmProjects\ByteProject\venv\Lib\site-packages\openpyxl\writer\excel.py", line 291, in save_workbook
    archive = ZipFile(filename, 'w', ZIP_DEFLATED, allowZip64=True)
              ^^^^^^^^^^^^^^^^^^^^^^^^^^^^^^^^^^^^^^^^^^^^^^^^^^^^^
  File "C:\Program Files\WindowsApps\PythonSoftwareFoundation.Python.3.12_3.12.2032.0_x64__qbz5n2kfra8p0\Lib\zipfile\__init__.py", line 1331, in __init__
    self.fp = io.open(file, filemode)
              ^^^^^^^^^^^^^^^^^^^^^^^
PermissionError: [Errno 13] Permission denied: 'tmp\\data.xlsx'
======================== content ========================: 
ABC123qwertyui
2024-10-20 20:32:24,382 - __main__ - ERROR - excel_index: 17 | test_index: 1 | attempt_time: 2 problem failed！
======================== wrong message ========================: 
[Errno 13] Permission denied: 'tmp\\data.xlsx'
======================== trace back ========================: 
Traceback (most recent call last):
  File "C:\Users\Admin\PycharmProjects\ByteProject\doubao\origin\v2\parallel\parallel_test.py", line 162, in request
    write_excel(excel_content)
  File "C:\Users\Admin\PycharmProjects\ByteProject\doubao\origin\v2\parallel\parallel_test.py", line 265, in write_excel
    CONSTANTS.excel_info["workbook"].save(CONSTANTS.excel_info["excel_path"])
  File "C:\Users\Admin\PycharmProjects\ByteProject\venv\Lib\site-packages\openpyxl\workbook\workbook.py", line 386, in save
    save_workbook(self, filename)
  File "C:\Users\Admin\PycharmProjects\ByteProject\venv\Lib\site-packages\openpyxl\writer\excel.py", line 291, in save_workbook
    archive = ZipFile(filename, 'w', ZIP_DEFLATED, allowZip64=True)
              ^^^^^^^^^^^^^^^^^^^^^^^^^^^^^^^^^^^^^^^^^^^^^^^^^^^^^
  File "C:\Program Files\WindowsApps\PythonSoftwareFoundation.Python.3.12_3.12.2032.0_x64__qbz5n2kfra8p0\Lib\zipfile\__init__.py", line 1331, in __init__
    self.fp = io.open(file, filemode)
              ^^^^^^^^^^^^^^^^^^^^^^^
PermissionError: [Errno 13] Permission denied: 'tmp\\data.xlsx'
======================== content ========================: 
ABC123qwer
2024-10-20 20:32:24,385 - __main__ - ERROR - excel_index: 21 | test_index: 2 | attempt_time: 2 problem failed！
======================== wrong message ========================: 
[Errno 13] Permission denied: 'tmp\\data.xlsx'
======================== trace back ========================: 
Traceback (most recent call last):
  File "C:\Users\Admin\PycharmProjects\ByteProject\doubao\origin\v2\parallel\parallel_test.py", line 162, in request
    write_excel(excel_content)
  File "C:\Users\Admin\PycharmProjects\ByteProject\doubao\origin\v2\parallel\parallel_test.py", line 265, in write_excel
    CONSTANTS.excel_info["workbook"].save(CONSTANTS.excel_info["excel_path"])
  File "C:\Users\Admin\PycharmProjects\ByteProject\venv\Lib\site-packages\openpyxl\workbook\workbook.py", line 386, in save
    save_workbook(self, filename)
  File "C:\Users\Admin\PycharmProjects\ByteProject\venv\Lib\site-packages\openpyxl\writer\excel.py", line 291, in save_workbook
    archive = ZipFile(filename, 'w', ZIP_DEFLATED, allowZip64=True)
              ^^^^^^^^^^^^^^^^^^^^^^^^^^^^^^^^^^^^^^^^^^^^^^^^^^^^^
  File "C:\Program Files\WindowsApps\PythonSoftwareFoundation.Python.3.12_3.12.2032.0_x64__qbz5n2kfra8p0\Lib\zipfile\__init__.py", line 1331, in __init__
    self.fp = io.open(file, filemode)
              ^^^^^^^^^^^^^^^^^^^^^^^
PermissionError: [Errno 13] Permission denied: 'tmp\\data.xlsx'
======================== content ========================: 
ABC123qwertyui
2024-10-20 20:32:24,403 - __main__ - ERROR - excel_index: 15 | test_index: 1 | attempt_time: 2 problem failed！
======================== wrong message ========================: 
[Errno 13] Permission denied: 'tmp\\data.xlsx'
======================== trace back ========================: 
Traceback (most recent call last):
  File "C:\Users\Admin\PycharmProjects\ByteProject\doubao\origin\v2\parallel\parallel_test.py", line 162, in request
    write_excel(excel_content)
  File "C:\Users\Admin\PycharmProjects\ByteProject\doubao\origin\v2\parallel\parallel_test.py", line 265, in write_excel
    CONSTANTS.excel_info["workbook"].save(CONSTANTS.excel_info["excel_path"])
  File "C:\Users\Admin\PycharmProjects\ByteProject\venv\Lib\site-packages\openpyxl\workbook\workbook.py", line 386, in save
    save_workbook(self, filename)
  File "C:\Users\Admin\PycharmProjects\ByteProject\venv\Lib\site-packages\openpyxl\writer\excel.py", line 291, in save_workbook
    archive = ZipFile(filename, 'w', ZIP_DEFLATED, allowZip64=True)
              ^^^^^^^^^^^^^^^^^^^^^^^^^^^^^^^^^^^^^^^^^^^^^^^^^^^^^
  File "C:\Program Files\WindowsApps\PythonSoftwareFoundation.Python.3.12_3.12.2032.0_x64__qbz5n2kfra8p0\Lib\zipfile\__init__.py", line 1331, in __init__
    self.fp = io.open(file, filemode)
              ^^^^^^^^^^^^^^^^^^^^^^^
PermissionError: [Errno 13] Permission denied: 'tmp\\data.xlsx'
======================== content ========================: 
ABC123qwer
2024-10-20 20:32:24,456 - __main__ - ERROR - excel_index: 7 | test_index: 0 | attempt_time: 2 problem failed！
======================== wrong message ========================: 
[Errno 13] Permission denied: 'tmp\\data.xlsx'
======================== trace back ========================: 
Traceback (most recent call last):
  File "C:\Users\Admin\PycharmProjects\ByteProject\doubao\origin\v2\parallel\parallel_test.py", line 162, in request
    write_excel(excel_content)
  File "C:\Users\Admin\PycharmProjects\ByteProject\doubao\origin\v2\parallel\parallel_test.py", line 265, in write_excel
    CONSTANTS.excel_info["workbook"].save(CONSTANTS.excel_info["excel_path"])
  File "C:\Users\Admin\PycharmProjects\ByteProject\venv\Lib\site-packages\openpyxl\workbook\workbook.py", line 386, in save
    save_workbook(self, filename)
  File "C:\Users\Admin\PycharmProjects\ByteProject\venv\Lib\site-packages\openpyxl\writer\excel.py", line 291, in save_workbook
    archive = ZipFile(filename, 'w', ZIP_DEFLATED, allowZip64=True)
              ^^^^^^^^^^^^^^^^^^^^^^^^^^^^^^^^^^^^^^^^^^^^^^^^^^^^^
  File "C:\Program Files\WindowsApps\PythonSoftwareFoundation.Python.3.12_3.12.2032.0_x64__qbz5n2kfra8p0\Lib\zipfile\__init__.py", line 1331, in __init__
    self.fp = io.open(file, filemode)
              ^^^^^^^^^^^^^^^^^^^^^^^
PermissionError: [Errno 13] Permission denied: 'tmp\\data.xlsx'
======================== content ========================: 
ABC123
2024-10-20 20:32:24,580 - __main__ - ERROR - excel_index: 28 | test_index: 2 | attempt_time: 2 problem failed！
======================== wrong message ========================: 
[Errno 13] Permission denied: 'tmp\\data.xlsx'
======================== trace back ========================: 
Traceback (most recent call last):
  File "C:\Users\Admin\PycharmProjects\ByteProject\doubao\origin\v2\parallel\parallel_test.py", line 162, in request
    write_excel(excel_content)
  File "C:\Users\Admin\PycharmProjects\ByteProject\doubao\origin\v2\parallel\parallel_test.py", line 265, in write_excel
    CONSTANTS.excel_info["workbook"].save(CONSTANTS.excel_info["excel_path"])
  File "C:\Users\Admin\PycharmProjects\ByteProject\venv\Lib\site-packages\openpyxl\workbook\workbook.py", line 386, in save
    save_workbook(self, filename)
  File "C:\Users\Admin\PycharmProjects\ByteProject\venv\Lib\site-packages\openpyxl\writer\excel.py", line 291, in save_workbook
    archive = ZipFile(filename, 'w', ZIP_DEFLATED, allowZip64=True)
              ^^^^^^^^^^^^^^^^^^^^^^^^^^^^^^^^^^^^^^^^^^^^^^^^^^^^^
  File "C:\Program Files\WindowsApps\PythonSoftwareFoundation.Python.3.12_3.12.2032.0_x64__qbz5n2kfra8p0\Lib\zipfile\__init__.py", line 1331, in __init__
    self.fp = io.open(file, filemode)
              ^^^^^^^^^^^^^^^^^^^^^^^
PermissionError: [Errno 13] Permission denied: 'tmp\\data.xlsx'
======================== content ========================: 
ABC123qwertyui
2024-10-20 20:32:24,583 - __main__ - ERROR - excel_index: 22 | test_index: 2 | attempt_time: 2 problem failed！
======================== wrong message ========================: 
[Errno 13] Permission denied: 'tmp\\data.xlsx'
======================== trace back ========================: 
Traceback (most recent call last):
  File "C:\Users\Admin\PycharmProjects\ByteProject\doubao\origin\v2\parallel\parallel_test.py", line 162, in request
    write_excel(excel_content)
  File "C:\Users\Admin\PycharmProjects\ByteProject\doubao\origin\v2\parallel\parallel_test.py", line 265, in write_excel
    CONSTANTS.excel_info["workbook"].save(CONSTANTS.excel_info["excel_path"])
  File "C:\Users\Admin\PycharmProjects\ByteProject\venv\Lib\site-packages\openpyxl\workbook\workbook.py", line 386, in save
    save_workbook(self, filename)
  File "C:\Users\Admin\PycharmProjects\ByteProject\venv\Lib\site-packages\openpyxl\writer\excel.py", line 291, in save_workbook
    archive = ZipFile(filename, 'w', ZIP_DEFLATED, allowZip64=True)
              ^^^^^^^^^^^^^^^^^^^^^^^^^^^^^^^^^^^^^^^^^^^^^^^^^^^^^
  File "C:\Program Files\WindowsApps\PythonSoftwareFoundation.Python.3.12_3.12.2032.0_x64__qbz5n2kfra8p0\Lib\zipfile\__init__.py", line 1331, in __init__
    self.fp = io.open(file, filemode)
              ^^^^^^^^^^^^^^^^^^^^^^^
PermissionError: [Errno 13] Permission denied: 'tmp\\data.xlsx'
======================== content ========================: 
ABC123qwertyui
2024-10-20 20:32:24,584 - __main__ - ERROR - excel_index: 26 | test_index: 2 | attempt_time: 2 problem failed！
======================== wrong message ========================: 
[Errno 13] Permission denied: 'tmp\\data.xlsx'
======================== trace back ========================: 
Traceback (most recent call last):
  File "C:\Users\Admin\PycharmProjects\ByteProject\doubao\origin\v2\parallel\parallel_test.py", line 162, in request
    write_excel(excel_content)
  File "C:\Users\Admin\PycharmProjects\ByteProject\doubao\origin\v2\parallel\parallel_test.py", line 265, in write_excel
    CONSTANTS.excel_info["workbook"].save(CONSTANTS.excel_info["excel_path"])
  File "C:\Users\Admin\PycharmProjects\ByteProject\venv\Lib\site-packages\openpyxl\workbook\workbook.py", line 386, in save
    save_workbook(self, filename)
  File "C:\Users\Admin\PycharmProjects\ByteProject\venv\Lib\site-packages\openpyxl\writer\excel.py", line 291, in save_workbook
    archive = ZipFile(filename, 'w', ZIP_DEFLATED, allowZip64=True)
              ^^^^^^^^^^^^^^^^^^^^^^^^^^^^^^^^^^^^^^^^^^^^^^^^^^^^^
  File "C:\Program Files\WindowsApps\PythonSoftwareFoundation.Python.3.12_3.12.2032.0_x64__qbz5n2kfra8p0\Lib\zipfile\__init__.py", line 1331, in __init__
    self.fp = io.open(file, filemode)
              ^^^^^^^^^^^^^^^^^^^^^^^
PermissionError: [Errno 13] Permission denied: 'tmp\\data.xlsx'
======================== content ========================: 
ABC123qwertyui
2024-10-20 20:32:24,586 - __main__ - ERROR - excel_index: 29 | test_index: 2 | attempt_time: 2 problem failed！
======================== wrong message ========================: 
[Errno 13] Permission denied: 'tmp\\data.xlsx'
======================== trace back ========================: 
Traceback (most recent call last):
  File "C:\Users\Admin\PycharmProjects\ByteProject\doubao\origin\v2\parallel\parallel_test.py", line 162, in request
    write_excel(excel_content)
  File "C:\Users\Admin\PycharmProjects\ByteProject\doubao\origin\v2\parallel\parallel_test.py", line 265, in write_excel
    CONSTANTS.excel_info["workbook"].save(CONSTANTS.excel_info["excel_path"])
  File "C:\Users\Admin\PycharmProjects\ByteProject\venv\Lib\site-packages\openpyxl\workbook\workbook.py", line 386, in save
    save_workbook(self, filename)
  File "C:\Users\Admin\PycharmProjects\ByteProject\venv\Lib\site-packages\openpyxl\writer\excel.py", line 291, in save_workbook
    archive = ZipFile(filename, 'w', ZIP_DEFLATED, allowZip64=True)
              ^^^^^^^^^^^^^^^^^^^^^^^^^^^^^^^^^^^^^^^^^^^^^^^^^^^^^
  File "C:\Program Files\WindowsApps\PythonSoftwareFoundation.Python.3.12_3.12.2032.0_x64__qbz5n2kfra8p0\Lib\zipfile\__init__.py", line 1331, in __init__
    self.fp = io.open(file, filemode)
              ^^^^^^^^^^^^^^^^^^^^^^^
PermissionError: [Errno 13] Permission denied: 'tmp\\data.xlsx'
======================== content ========================: 
ABC123qwertyui
2024-10-20 20:32:24,590 - __main__ - ERROR - excel_index: 34 | test_index: 3 | attempt_time: 2 problem failed！
======================== wrong message ========================: 
[Errno 13] Permission denied: 'tmp\\data.xlsx'
======================== trace back ========================: 
Traceback (most recent call last):
  File "C:\Users\Admin\PycharmProjects\ByteProject\doubao\origin\v2\parallel\parallel_test.py", line 162, in request
    write_excel(excel_content)
  File "C:\Users\Admin\PycharmProjects\ByteProject\doubao\origin\v2\parallel\parallel_test.py", line 265, in write_excel
    CONSTANTS.excel_info["workbook"].save(CONSTANTS.excel_info["excel_path"])
  File "C:\Users\Admin\PycharmProjects\ByteProject\venv\Lib\site-packages\openpyxl\workbook\workbook.py", line 386, in save
    save_workbook(self, filename)
  File "C:\Users\Admin\PycharmProjects\ByteProject\venv\Lib\site-packages\openpyxl\writer\excel.py", line 291, in save_workbook
    archive = ZipFile(filename, 'w', ZIP_DEFLATED, allowZip64=True)
              ^^^^^^^^^^^^^^^^^^^^^^^^^^^^^^^^^^^^^^^^^^^^^^^^^^^^^
  File "C:\Program Files\WindowsApps\PythonSoftwareFoundation.Python.3.12_3.12.2032.0_x64__qbz5n2kfra8p0\Lib\zipfile\__init__.py", line 1331, in __init__
    self.fp = io.open(file, filemode)
              ^^^^^^^^^^^^^^^^^^^^^^^
PermissionError: [Errno 13] Permission denied: 'tmp\\data.xlsx'
======================== content ========================: 
ABC123qwertyuiopas
2024-10-20 20:32:24,809 - __main__ - ERROR - excel_index: 40 | test_index: 4 | attempt_time: 2 problem failed！
======================== wrong message ========================: 
[Errno 13] Permission denied: 'tmp\\data.xlsx'
======================== trace back ========================: 
Traceback (most recent call last):
  File "C:\Users\Admin\PycharmProjects\ByteProject\doubao\origin\v2\parallel\parallel_test.py", line 162, in request
    write_excel(excel_content)
  File "C:\Users\Admin\PycharmProjects\ByteProject\doubao\origin\v2\parallel\parallel_test.py", line 265, in write_excel
    CONSTANTS.excel_info["workbook"].save(CONSTANTS.excel_info["excel_path"])
  File "C:\Users\Admin\PycharmProjects\ByteProject\venv\Lib\site-packages\openpyxl\workbook\workbook.py", line 386, in save
    save_workbook(self, filename)
  File "C:\Users\Admin\PycharmProjects\ByteProject\venv\Lib\site-packages\openpyxl\writer\excel.py", line 291, in save_workbook
    archive = ZipFile(filename, 'w', ZIP_DEFLATED, allowZip64=True)
              ^^^^^^^^^^^^^^^^^^^^^^^^^^^^^^^^^^^^^^^^^^^^^^^^^^^^^
  File "C:\Program Files\WindowsApps\PythonSoftwareFoundation.Python.3.12_3.12.2032.0_x64__qbz5n2kfra8p0\Lib\zipfile\__init__.py", line 1331, in __init__
    self.fp = io.open(file, filemode)
              ^^^^^^^^^^^^^^^^^^^^^^^
PermissionError: [Errno 13] Permission denied: 'tmp\\data.xlsx'
======================== content ========================: 
ABC123qwertyuiopasd
2024-10-20 20:32:24,810 - __main__ - ERROR - excel_index: 39 | test_index: 3 | attempt_time: 2 problem failed！
======================== wrong message ========================: 
[Errno 13] Permission denied: 'tmp\\data.xlsx'
======================== trace back ========================: 
Traceback (most recent call last):
  File "C:\Users\Admin\PycharmProjects\ByteProject\doubao\origin\v2\parallel\parallel_test.py", line 162, in request
    write_excel(excel_content)
  File "C:\Users\Admin\PycharmProjects\ByteProject\doubao\origin\v2\parallel\parallel_test.py", line 265, in write_excel
    CONSTANTS.excel_info["workbook"].save(CONSTANTS.excel_info["excel_path"])
  File "C:\Users\Admin\PycharmProjects\ByteProject\venv\Lib\site-packages\openpyxl\workbook\workbook.py", line 386, in save
    save_workbook(self, filename)
  File "C:\Users\Admin\PycharmProjects\ByteProject\venv\Lib\site-packages\openpyxl\writer\excel.py", line 291, in save_workbook
    archive = ZipFile(filename, 'w', ZIP_DEFLATED, allowZip64=True)
              ^^^^^^^^^^^^^^^^^^^^^^^^^^^^^^^^^^^^^^^^^^^^^^^^^^^^^
  File "C:\Program Files\WindowsApps\PythonSoftwareFoundation.Python.3.12_3.12.2032.0_x64__qbz5n2kfra8p0\Lib\zipfile\__init__.py", line 1331, in __init__
    self.fp = io.open(file, filemode)
              ^^^^^^^^^^^^^^^^^^^^^^^
PermissionError: [Errno 13] Permission denied: 'tmp\\data.xlsx'
======================== content ========================: 
ABC123qwertyuiopas
2024-10-20 20:32:24,813 - __main__ - ERROR - excel_index: 32 | test_index: 3 | attempt_time: 2 problem failed！
======================== wrong message ========================: 
[Errno 13] Permission denied: 'tmp\\data.xlsx'
======================== trace back ========================: 
Traceback (most recent call last):
  File "C:\Users\Admin\PycharmProjects\ByteProject\doubao\origin\v2\parallel\parallel_test.py", line 162, in request
    write_excel(excel_content)
  File "C:\Users\Admin\PycharmProjects\ByteProject\doubao\origin\v2\parallel\parallel_test.py", line 265, in write_excel
    CONSTANTS.excel_info["workbook"].save(CONSTANTS.excel_info["excel_path"])
  File "C:\Users\Admin\PycharmProjects\ByteProject\venv\Lib\site-packages\openpyxl\workbook\workbook.py", line 386, in save
    save_workbook(self, filename)
  File "C:\Users\Admin\PycharmProjects\ByteProject\venv\Lib\site-packages\openpyxl\writer\excel.py", line 291, in save_workbook
    archive = ZipFile(filename, 'w', ZIP_DEFLATED, allowZip64=True)
              ^^^^^^^^^^^^^^^^^^^^^^^^^^^^^^^^^^^^^^^^^^^^^^^^^^^^^
  File "C:\Program Files\WindowsApps\PythonSoftwareFoundation.Python.3.12_3.12.2032.0_x64__qbz5n2kfra8p0\Lib\zipfile\__init__.py", line 1331, in __init__
    self.fp = io.open(file, filemode)
              ^^^^^^^^^^^^^^^^^^^^^^^
PermissionError: [Errno 13] Permission denied: 'tmp\\data.xlsx'
======================== content ========================: 
ABC123qwertyuiopas
2024-10-20 20:32:24,815 - __main__ - ERROR - excel_index: 44 | test_index: 4 | attempt_time: 2 problem failed！
======================== wrong message ========================: 
[Errno 13] Permission denied: 'tmp\\data.xlsx'
======================== trace back ========================: 
Traceback (most recent call last):
  File "C:\Users\Admin\PycharmProjects\ByteProject\doubao\origin\v2\parallel\parallel_test.py", line 162, in request
    write_excel(excel_content)
  File "C:\Users\Admin\PycharmProjects\ByteProject\doubao\origin\v2\parallel\parallel_test.py", line 265, in write_excel
    CONSTANTS.excel_info["workbook"].save(CONSTANTS.excel_info["excel_path"])
  File "C:\Users\Admin\PycharmProjects\ByteProject\venv\Lib\site-packages\openpyxl\workbook\workbook.py", line 386, in save
    save_workbook(self, filename)
  File "C:\Users\Admin\PycharmProjects\ByteProject\venv\Lib\site-packages\openpyxl\writer\excel.py", line 291, in save_workbook
    archive = ZipFile(filename, 'w', ZIP_DEFLATED, allowZip64=True)
              ^^^^^^^^^^^^^^^^^^^^^^^^^^^^^^^^^^^^^^^^^^^^^^^^^^^^^
  File "C:\Program Files\WindowsApps\PythonSoftwareFoundation.Python.3.12_3.12.2032.0_x64__qbz5n2kfra8p0\Lib\zipfile\__init__.py", line 1331, in __init__
    self.fp = io.open(file, filemode)
              ^^^^^^^^^^^^^^^^^^^^^^^
PermissionError: [Errno 13] Permission denied: 'tmp\\data.xlsx'
======================== content ========================: 
ABC123qwertyuiopasd
2024-10-20 20:32:24,818 - __main__ - ERROR - excel_index: 33 | test_index: 3 | attempt_time: 2 problem failed！
======================== wrong message ========================: 
[Errno 13] Permission denied: 'tmp\\data.xlsx'
======================== trace back ========================: 
Traceback (most recent call last):
  File "C:\Users\Admin\PycharmProjects\ByteProject\doubao\origin\v2\parallel\parallel_test.py", line 162, in request
    write_excel(excel_content)
  File "C:\Users\Admin\PycharmProjects\ByteProject\doubao\origin\v2\parallel\parallel_test.py", line 265, in write_excel
    CONSTANTS.excel_info["workbook"].save(CONSTANTS.excel_info["excel_path"])
  File "C:\Users\Admin\PycharmProjects\ByteProject\venv\Lib\site-packages\openpyxl\workbook\workbook.py", line 386, in save
    save_workbook(self, filename)
  File "C:\Users\Admin\PycharmProjects\ByteProject\venv\Lib\site-packages\openpyxl\writer\excel.py", line 291, in save_workbook
    archive = ZipFile(filename, 'w', ZIP_DEFLATED, allowZip64=True)
              ^^^^^^^^^^^^^^^^^^^^^^^^^^^^^^^^^^^^^^^^^^^^^^^^^^^^^
  File "C:\Program Files\WindowsApps\PythonSoftwareFoundation.Python.3.12_3.12.2032.0_x64__qbz5n2kfra8p0\Lib\zipfile\__init__.py", line 1331, in __init__
    self.fp = io.open(file, filemode)
              ^^^^^^^^^^^^^^^^^^^^^^^
PermissionError: [Errno 13] Permission denied: 'tmp\\data.xlsx'
======================== content ========================: 
ABC123qwertyuiopas
2024-10-20 20:32:24,820 - __main__ - ERROR - excel_index: 35 | test_index: 3 | attempt_time: 2 problem failed！
======================== wrong message ========================: 
[Errno 13] Permission denied: 'tmp\\data.xlsx'
======================== trace back ========================: 
Traceback (most recent call last):
  File "C:\Users\Admin\PycharmProjects\ByteProject\doubao\origin\v2\parallel\parallel_test.py", line 162, in request
    write_excel(excel_content)
  File "C:\Users\Admin\PycharmProjects\ByteProject\doubao\origin\v2\parallel\parallel_test.py", line 265, in write_excel
    CONSTANTS.excel_info["workbook"].save(CONSTANTS.excel_info["excel_path"])
  File "C:\Users\Admin\PycharmProjects\ByteProject\venv\Lib\site-packages\openpyxl\workbook\workbook.py", line 386, in save
    save_workbook(self, filename)
  File "C:\Users\Admin\PycharmProjects\ByteProject\venv\Lib\site-packages\openpyxl\writer\excel.py", line 291, in save_workbook
    archive = ZipFile(filename, 'w', ZIP_DEFLATED, allowZip64=True)
              ^^^^^^^^^^^^^^^^^^^^^^^^^^^^^^^^^^^^^^^^^^^^^^^^^^^^^
  File "C:\Program Files\WindowsApps\PythonSoftwareFoundation.Python.3.12_3.12.2032.0_x64__qbz5n2kfra8p0\Lib\zipfile\__init__.py", line 1331, in __init__
    self.fp = io.open(file, filemode)
              ^^^^^^^^^^^^^^^^^^^^^^^
PermissionError: [Errno 13] Permission denied: 'tmp\\data.xlsx'
======================== content ========================: 
ABC123qwertyuiopas
2024-10-20 20:32:24,821 - __main__ - ERROR - excel_index: 30 | test_index: 3 | attempt_time: 2 problem failed！
======================== wrong message ========================: 
[Errno 13] Permission denied: 'tmp\\data.xlsx'
======================== trace back ========================: 
Traceback (most recent call last):
  File "C:\Users\Admin\PycharmProjects\ByteProject\doubao\origin\v2\parallel\parallel_test.py", line 162, in request
    write_excel(excel_content)
  File "C:\Users\Admin\PycharmProjects\ByteProject\doubao\origin\v2\parallel\parallel_test.py", line 265, in write_excel
    CONSTANTS.excel_info["workbook"].save(CONSTANTS.excel_info["excel_path"])
  File "C:\Users\Admin\PycharmProjects\ByteProject\venv\Lib\site-packages\openpyxl\workbook\workbook.py", line 386, in save
    save_workbook(self, filename)
  File "C:\Users\Admin\PycharmProjects\ByteProject\venv\Lib\site-packages\openpyxl\writer\excel.py", line 291, in save_workbook
    archive = ZipFile(filename, 'w', ZIP_DEFLATED, allowZip64=True)
              ^^^^^^^^^^^^^^^^^^^^^^^^^^^^^^^^^^^^^^^^^^^^^^^^^^^^^
  File "C:\Program Files\WindowsApps\PythonSoftwareFoundation.Python.3.12_3.12.2032.0_x64__qbz5n2kfra8p0\Lib\zipfile\__init__.py", line 1331, in __init__
    self.fp = io.open(file, filemode)
              ^^^^^^^^^^^^^^^^^^^^^^^
PermissionError: [Errno 13] Permission denied: 'tmp\\data.xlsx'
======================== content ========================: 
ABC123qwertyuiopas
2024-10-20 20:32:24,842 - __main__ - ERROR - excel_index: 49 | test_index: 4 | attempt_time: 2 problem failed！
======================== wrong message ========================: 
[Errno 13] Permission denied: 'tmp\\data.xlsx'
======================== trace back ========================: 
Traceback (most recent call last):
  File "C:\Users\Admin\PycharmProjects\ByteProject\doubao\origin\v2\parallel\parallel_test.py", line 162, in request
    write_excel(excel_content)
  File "C:\Users\Admin\PycharmProjects\ByteProject\doubao\origin\v2\parallel\parallel_test.py", line 265, in write_excel
    CONSTANTS.excel_info["workbook"].save(CONSTANTS.excel_info["excel_path"])
  File "C:\Users\Admin\PycharmProjects\ByteProject\venv\Lib\site-packages\openpyxl\workbook\workbook.py", line 386, in save
    save_workbook(self, filename)
  File "C:\Users\Admin\PycharmProjects\ByteProject\venv\Lib\site-packages\openpyxl\writer\excel.py", line 291, in save_workbook
    archive = ZipFile(filename, 'w', ZIP_DEFLATED, allowZip64=True)
              ^^^^^^^^^^^^^^^^^^^^^^^^^^^^^^^^^^^^^^^^^^^^^^^^^^^^^
  File "C:\Program Files\WindowsApps\PythonSoftwareFoundation.Python.3.12_3.12.2032.0_x64__qbz5n2kfra8p0\Lib\zipfile\__init__.py", line 1331, in __init__
    self.fp = io.open(file, filemode)
              ^^^^^^^^^^^^^^^^^^^^^^^
PermissionError: [Errno 13] Permission denied: 'tmp\\data.xlsx'
======================== content ========================: 
ABC123qwertyuiopasd
2024-10-20 20:32:24,913 - __main__ - ERROR - excel_index: 47 | test_index: 4 | attempt_time: 2 problem failed！
======================== wrong message ========================: 
[Errno 13] Permission denied: 'tmp\\data.xlsx'
======================== trace back ========================: 
Traceback (most recent call last):
  File "C:\Users\Admin\PycharmProjects\ByteProject\doubao\origin\v2\parallel\parallel_test.py", line 162, in request
    write_excel(excel_content)
  File "C:\Users\Admin\PycharmProjects\ByteProject\doubao\origin\v2\parallel\parallel_test.py", line 265, in write_excel
    CONSTANTS.excel_info["workbook"].save(CONSTANTS.excel_info["excel_path"])
  File "C:\Users\Admin\PycharmProjects\ByteProject\venv\Lib\site-packages\openpyxl\workbook\workbook.py", line 386, in save
    save_workbook(self, filename)
  File "C:\Users\Admin\PycharmProjects\ByteProject\venv\Lib\site-packages\openpyxl\writer\excel.py", line 291, in save_workbook
    archive = ZipFile(filename, 'w', ZIP_DEFLATED, allowZip64=True)
              ^^^^^^^^^^^^^^^^^^^^^^^^^^^^^^^^^^^^^^^^^^^^^^^^^^^^^
  File "C:\Program Files\WindowsApps\PythonSoftwareFoundation.Python.3.12_3.12.2032.0_x64__qbz5n2kfra8p0\Lib\zipfile\__init__.py", line 1331, in __init__
    self.fp = io.open(file, filemode)
              ^^^^^^^^^^^^^^^^^^^^^^^
PermissionError: [Errno 13] Permission denied: 'tmp\\data.xlsx'
======================== content ========================: 
ABC123qwertyuiopasd
2024-10-20 20:32:24,948 - __main__ - ERROR - excel_index: 38 | test_index: 3 | attempt_time: 2 problem failed！
======================== wrong message ========================: 
[Errno 13] Permission denied: 'tmp\\data.xlsx'
======================== trace back ========================: 
Traceback (most recent call last):
  File "C:\Users\Admin\PycharmProjects\ByteProject\doubao\origin\v2\parallel\parallel_test.py", line 162, in request
    write_excel(excel_content)
  File "C:\Users\Admin\PycharmProjects\ByteProject\doubao\origin\v2\parallel\parallel_test.py", line 265, in write_excel
    CONSTANTS.excel_info["workbook"].save(CONSTANTS.excel_info["excel_path"])
  File "C:\Users\Admin\PycharmProjects\ByteProject\venv\Lib\site-packages\openpyxl\workbook\workbook.py", line 386, in save
    save_workbook(self, filename)
  File "C:\Users\Admin\PycharmProjects\ByteProject\venv\Lib\site-packages\openpyxl\writer\excel.py", line 291, in save_workbook
    archive = ZipFile(filename, 'w', ZIP_DEFLATED, allowZip64=True)
              ^^^^^^^^^^^^^^^^^^^^^^^^^^^^^^^^^^^^^^^^^^^^^^^^^^^^^
  File "C:\Program Files\WindowsApps\PythonSoftwareFoundation.Python.3.12_3.12.2032.0_x64__qbz5n2kfra8p0\Lib\zipfile\__init__.py", line 1331, in __init__
    self.fp = io.open(file, filemode)
              ^^^^^^^^^^^^^^^^^^^^^^^
PermissionError: [Errno 13] Permission denied: 'tmp\\data.xlsx'
======================== content ========================: 
ABC123qwertyuiopas
2024-10-20 20:32:24,971 - __main__ - ERROR - excel_index: 41 | test_index: 4 | attempt_time: 2 problem failed！
======================== wrong message ========================: 
[Errno 13] Permission denied: 'tmp\\data.xlsx'
======================== trace back ========================: 
Traceback (most recent call last):
  File "C:\Users\Admin\PycharmProjects\ByteProject\doubao\origin\v2\parallel\parallel_test.py", line 162, in request
    write_excel(excel_content)
  File "C:\Users\Admin\PycharmProjects\ByteProject\doubao\origin\v2\parallel\parallel_test.py", line 265, in write_excel
    CONSTANTS.excel_info["workbook"].save(CONSTANTS.excel_info["excel_path"])
  File "C:\Users\Admin\PycharmProjects\ByteProject\venv\Lib\site-packages\openpyxl\workbook\workbook.py", line 386, in save
    save_workbook(self, filename)
  File "C:\Users\Admin\PycharmProjects\ByteProject\venv\Lib\site-packages\openpyxl\writer\excel.py", line 291, in save_workbook
    archive = ZipFile(filename, 'w', ZIP_DEFLATED, allowZip64=True)
              ^^^^^^^^^^^^^^^^^^^^^^^^^^^^^^^^^^^^^^^^^^^^^^^^^^^^^
  File "C:\Program Files\WindowsApps\PythonSoftwareFoundation.Python.3.12_3.12.2032.0_x64__qbz5n2kfra8p0\Lib\zipfile\__init__.py", line 1331, in __init__
    self.fp = io.open(file, filemode)
              ^^^^^^^^^^^^^^^^^^^^^^^
PermissionError: [Errno 13] Permission denied: 'tmp\\data.xlsx'
======================== content ========================: 
ABC123qwertyuiopasd
2024-10-20 20:32:24,993 - __main__ - ERROR - excel_index: 37 | test_index: 3 | attempt_time: 2 problem failed！
======================== wrong message ========================: 
[Errno 13] Permission denied: 'tmp\\data.xlsx'
======================== trace back ========================: 
Traceback (most recent call last):
  File "C:\Users\Admin\PycharmProjects\ByteProject\doubao\origin\v2\parallel\parallel_test.py", line 162, in request
    write_excel(excel_content)
  File "C:\Users\Admin\PycharmProjects\ByteProject\doubao\origin\v2\parallel\parallel_test.py", line 265, in write_excel
    CONSTANTS.excel_info["workbook"].save(CONSTANTS.excel_info["excel_path"])
  File "C:\Users\Admin\PycharmProjects\ByteProject\venv\Lib\site-packages\openpyxl\workbook\workbook.py", line 386, in save
    save_workbook(self, filename)
  File "C:\Users\Admin\PycharmProjects\ByteProject\venv\Lib\site-packages\openpyxl\writer\excel.py", line 291, in save_workbook
    archive = ZipFile(filename, 'w', ZIP_DEFLATED, allowZip64=True)
              ^^^^^^^^^^^^^^^^^^^^^^^^^^^^^^^^^^^^^^^^^^^^^^^^^^^^^
  File "C:\Program Files\WindowsApps\PythonSoftwareFoundation.Python.3.12_3.12.2032.0_x64__qbz5n2kfra8p0\Lib\zipfile\__init__.py", line 1331, in __init__
    self.fp = io.open(file, filemode)
              ^^^^^^^^^^^^^^^^^^^^^^^
PermissionError: [Errno 13] Permission denied: 'tmp\\data.xlsx'
======================== content ========================: 
ABC123qwertyuiopas
2024-10-20 20:32:25,147 - __main__ - ERROR - excel_index: 43 | test_index: 4 | attempt_time: 2 problem failed！
======================== wrong message ========================: 
[Errno 13] Permission denied: 'tmp\\data.xlsx'
======================== trace back ========================: 
Traceback (most recent call last):
  File "C:\Users\Admin\PycharmProjects\ByteProject\doubao\origin\v2\parallel\parallel_test.py", line 162, in request
    write_excel(excel_content)
  File "C:\Users\Admin\PycharmProjects\ByteProject\doubao\origin\v2\parallel\parallel_test.py", line 265, in write_excel
    CONSTANTS.excel_info["workbook"].save(CONSTANTS.excel_info["excel_path"])
  File "C:\Users\Admin\PycharmProjects\ByteProject\venv\Lib\site-packages\openpyxl\workbook\workbook.py", line 386, in save
    save_workbook(self, filename)
  File "C:\Users\Admin\PycharmProjects\ByteProject\venv\Lib\site-packages\openpyxl\writer\excel.py", line 291, in save_workbook
    archive = ZipFile(filename, 'w', ZIP_DEFLATED, allowZip64=True)
              ^^^^^^^^^^^^^^^^^^^^^^^^^^^^^^^^^^^^^^^^^^^^^^^^^^^^^
  File "C:\Program Files\WindowsApps\PythonSoftwareFoundation.Python.3.12_3.12.2032.0_x64__qbz5n2kfra8p0\Lib\zipfile\__init__.py", line 1331, in __init__
    self.fp = io.open(file, filemode)
              ^^^^^^^^^^^^^^^^^^^^^^^
PermissionError: [Errno 13] Permission denied: 'tmp\\data.xlsx'
======================== content ========================: 
ABC123qwertyuiopasd
2024-10-20 20:32:25,150 - __main__ - ERROR - excel_index: 20 | test_index: 2 | attempt_time: 2 problem failed！
======================== wrong message ========================: 
[Errno 13] Permission denied: 'tmp\\data.xlsx'
======================== trace back ========================: 
Traceback (most recent call last):
  File "C:\Users\Admin\PycharmProjects\ByteProject\doubao\origin\v2\parallel\parallel_test.py", line 162, in request
    write_excel(excel_content)
  File "C:\Users\Admin\PycharmProjects\ByteProject\doubao\origin\v2\parallel\parallel_test.py", line 265, in write_excel
    CONSTANTS.excel_info["workbook"].save(CONSTANTS.excel_info["excel_path"])
  File "C:\Users\Admin\PycharmProjects\ByteProject\venv\Lib\site-packages\openpyxl\workbook\workbook.py", line 386, in save
    save_workbook(self, filename)
  File "C:\Users\Admin\PycharmProjects\ByteProject\venv\Lib\site-packages\openpyxl\writer\excel.py", line 291, in save_workbook
    archive = ZipFile(filename, 'w', ZIP_DEFLATED, allowZip64=True)
              ^^^^^^^^^^^^^^^^^^^^^^^^^^^^^^^^^^^^^^^^^^^^^^^^^^^^^
  File "C:\Program Files\WindowsApps\PythonSoftwareFoundation.Python.3.12_3.12.2032.0_x64__qbz5n2kfra8p0\Lib\zipfile\__init__.py", line 1331, in __init__
    self.fp = io.open(file, filemode)
              ^^^^^^^^^^^^^^^^^^^^^^^
PermissionError: [Errno 13] Permission denied: 'tmp\\data.xlsx'
======================== content ========================: 
ABC123qwertyui
2024-10-20 20:32:25,153 - __main__ - ERROR - excel_index: 48 | test_index: 4 | attempt_time: 2 problem failed！
======================== wrong message ========================: 
[Errno 13] Permission denied: 'tmp\\data.xlsx'
======================== trace back ========================: 
Traceback (most recent call last):
  File "C:\Users\Admin\PycharmProjects\ByteProject\doubao\origin\v2\parallel\parallel_test.py", line 162, in request
    write_excel(excel_content)
  File "C:\Users\Admin\PycharmProjects\ByteProject\doubao\origin\v2\parallel\parallel_test.py", line 265, in write_excel
    CONSTANTS.excel_info["workbook"].save(CONSTANTS.excel_info["excel_path"])
  File "C:\Users\Admin\PycharmProjects\ByteProject\venv\Lib\site-packages\openpyxl\workbook\workbook.py", line 386, in save
    save_workbook(self, filename)
  File "C:\Users\Admin\PycharmProjects\ByteProject\venv\Lib\site-packages\openpyxl\writer\excel.py", line 291, in save_workbook
    archive = ZipFile(filename, 'w', ZIP_DEFLATED, allowZip64=True)
              ^^^^^^^^^^^^^^^^^^^^^^^^^^^^^^^^^^^^^^^^^^^^^^^^^^^^^
  File "C:\Program Files\WindowsApps\PythonSoftwareFoundation.Python.3.12_3.12.2032.0_x64__qbz5n2kfra8p0\Lib\zipfile\__init__.py", line 1331, in __init__
    self.fp = io.open(file, filemode)
              ^^^^^^^^^^^^^^^^^^^^^^^
PermissionError: [Errno 13] Permission denied: 'tmp\\data.xlsx'
======================== content ========================: 
ABC123qwertyuiopasd
2024-10-20 20:32:25,249 - __main__ - ERROR - excel_index: 42 | test_index: 4 | attempt_time: 2 problem failed！
======================== wrong message ========================: 
[Errno 13] Permission denied: 'tmp\\data.xlsx'
======================== trace back ========================: 
Traceback (most recent call last):
  File "C:\Users\Admin\PycharmProjects\ByteProject\doubao\origin\v2\parallel\parallel_test.py", line 162, in request
    write_excel(excel_content)
  File "C:\Users\Admin\PycharmProjects\ByteProject\doubao\origin\v2\parallel\parallel_test.py", line 265, in write_excel
    CONSTANTS.excel_info["workbook"].save(CONSTANTS.excel_info["excel_path"])
  File "C:\Users\Admin\PycharmProjects\ByteProject\venv\Lib\site-packages\openpyxl\workbook\workbook.py", line 386, in save
    save_workbook(self, filename)
  File "C:\Users\Admin\PycharmProjects\ByteProject\venv\Lib\site-packages\openpyxl\writer\excel.py", line 291, in save_workbook
    archive = ZipFile(filename, 'w', ZIP_DEFLATED, allowZip64=True)
              ^^^^^^^^^^^^^^^^^^^^^^^^^^^^^^^^^^^^^^^^^^^^^^^^^^^^^
  File "C:\Program Files\WindowsApps\PythonSoftwareFoundation.Python.3.12_3.12.2032.0_x64__qbz5n2kfra8p0\Lib\zipfile\__init__.py", line 1331, in __init__
    self.fp = io.open(file, filemode)
              ^^^^^^^^^^^^^^^^^^^^^^^
PermissionError: [Errno 13] Permission denied: 'tmp\\data.xlsx'
======================== content ========================: 
ABC123qwertyuiopasd
2024-10-20 20:32:25,384 - __main__ - ERROR - excel_index: 45 | test_index: 4 | attempt_time: 2 problem failed！
======================== wrong message ========================: 
[Errno 13] Permission denied: 'tmp\\data.xlsx'
======================== trace back ========================: 
Traceback (most recent call last):
  File "C:\Users\Admin\PycharmProjects\ByteProject\doubao\origin\v2\parallel\parallel_test.py", line 162, in request
    write_excel(excel_content)
  File "C:\Users\Admin\PycharmProjects\ByteProject\doubao\origin\v2\parallel\parallel_test.py", line 265, in write_excel
    CONSTANTS.excel_info["workbook"].save(CONSTANTS.excel_info["excel_path"])
  File "C:\Users\Admin\PycharmProjects\ByteProject\venv\Lib\site-packages\openpyxl\workbook\workbook.py", line 386, in save
    save_workbook(self, filename)
  File "C:\Users\Admin\PycharmProjects\ByteProject\venv\Lib\site-packages\openpyxl\writer\excel.py", line 291, in save_workbook
    archive = ZipFile(filename, 'w', ZIP_DEFLATED, allowZip64=True)
              ^^^^^^^^^^^^^^^^^^^^^^^^^^^^^^^^^^^^^^^^^^^^^^^^^^^^^
  File "C:\Program Files\WindowsApps\PythonSoftwareFoundation.Python.3.12_3.12.2032.0_x64__qbz5n2kfra8p0\Lib\zipfile\__init__.py", line 1331, in __init__
    self.fp = io.open(file, filemode)
              ^^^^^^^^^^^^^^^^^^^^^^^
PermissionError: [Errno 13] Permission denied: 'tmp\\data.xlsx'
======================== content ========================: 
ABC123qwertyuiopasd
2024-10-20 20:32:25,751 - __main__ - ERROR - excel_index: 23 | test_index: 2 | attempt_time: 2 problem failed！
======================== wrong message ========================: 
[Errno 13] Permission denied: 'tmp\\data.xlsx'
======================== trace back ========================: 
Traceback (most recent call last):
  File "C:\Users\Admin\PycharmProjects\ByteProject\doubao\origin\v2\parallel\parallel_test.py", line 162, in request
    write_excel(excel_content)
  File "C:\Users\Admin\PycharmProjects\ByteProject\doubao\origin\v2\parallel\parallel_test.py", line 265, in write_excel
    CONSTANTS.excel_info["workbook"].save(CONSTANTS.excel_info["excel_path"])
  File "C:\Users\Admin\PycharmProjects\ByteProject\venv\Lib\site-packages\openpyxl\workbook\workbook.py", line 386, in save
    save_workbook(self, filename)
  File "C:\Users\Admin\PycharmProjects\ByteProject\venv\Lib\site-packages\openpyxl\writer\excel.py", line 291, in save_workbook
    archive = ZipFile(filename, 'w', ZIP_DEFLATED, allowZip64=True)
              ^^^^^^^^^^^^^^^^^^^^^^^^^^^^^^^^^^^^^^^^^^^^^^^^^^^^^
  File "C:\Program Files\WindowsApps\PythonSoftwareFoundation.Python.3.12_3.12.2032.0_x64__qbz5n2kfra8p0\Lib\zipfile\__init__.py", line 1331, in __init__
    self.fp = io.open(file, filemode)
              ^^^^^^^^^^^^^^^^^^^^^^^
PermissionError: [Errno 13] Permission denied: 'tmp\\data.xlsx'
======================== content ========================: 
ABC123qwertyui
2024-10-20 20:32:25,932 - __main__ - ERROR - excel_index: 46 | test_index: 4 | attempt_time: 2 problem failed！
======================== wrong message ========================: 
[Errno 13] Permission denied: 'tmp\\data.xlsx'
======================== trace back ========================: 
Traceback (most recent call last):
  File "C:\Users\Admin\PycharmProjects\ByteProject\doubao\origin\v2\parallel\parallel_test.py", line 162, in request
    write_excel(excel_content)
  File "C:\Users\Admin\PycharmProjects\ByteProject\doubao\origin\v2\parallel\parallel_test.py", line 265, in write_excel
    CONSTANTS.excel_info["workbook"].save(CONSTANTS.excel_info["excel_path"])
  File "C:\Users\Admin\PycharmProjects\ByteProject\venv\Lib\site-packages\openpyxl\workbook\workbook.py", line 386, in save
    save_workbook(self, filename)
  File "C:\Users\Admin\PycharmProjects\ByteProject\venv\Lib\site-packages\openpyxl\writer\excel.py", line 291, in save_workbook
    archive = ZipFile(filename, 'w', ZIP_DEFLATED, allowZip64=True)
              ^^^^^^^^^^^^^^^^^^^^^^^^^^^^^^^^^^^^^^^^^^^^^^^^^^^^^
  File "C:\Program Files\WindowsApps\PythonSoftwareFoundation.Python.3.12_3.12.2032.0_x64__qbz5n2kfra8p0\Lib\zipfile\__init__.py", line 1331, in __init__
    self.fp = io.open(file, filemode)
              ^^^^^^^^^^^^^^^^^^^^^^^
PermissionError: [Errno 13] Permission denied: 'tmp\\data.xlsx'
======================== content ========================: 
ABC123qwertyuiopasd
2024-10-20 20:32:26,041 - __main__ - ERROR - excel_index: 10 | test_index: 1 | attempt_time: 2 problem failed！
======================== wrong message ========================: 
[Errno 13] Permission denied: 'tmp\\data.xlsx'
======================== trace back ========================: 
Traceback (most recent call last):
  File "C:\Users\Admin\PycharmProjects\ByteProject\doubao\origin\v2\parallel\parallel_test.py", line 162, in request
    write_excel(excel_content)
  File "C:\Users\Admin\PycharmProjects\ByteProject\doubao\origin\v2\parallel\parallel_test.py", line 265, in write_excel
    CONSTANTS.excel_info["workbook"].save(CONSTANTS.excel_info["excel_path"])
  File "C:\Users\Admin\PycharmProjects\ByteProject\venv\Lib\site-packages\openpyxl\workbook\workbook.py", line 386, in save
    save_workbook(self, filename)
  File "C:\Users\Admin\PycharmProjects\ByteProject\venv\Lib\site-packages\openpyxl\writer\excel.py", line 291, in save_workbook
    archive = ZipFile(filename, 'w', ZIP_DEFLATED, allowZip64=True)
              ^^^^^^^^^^^^^^^^^^^^^^^^^^^^^^^^^^^^^^^^^^^^^^^^^^^^^
  File "C:\Program Files\WindowsApps\PythonSoftwareFoundation.Python.3.12_3.12.2032.0_x64__qbz5n2kfra8p0\Lib\zipfile\__init__.py", line 1331, in __init__
    self.fp = io.open(file, filemode)
              ^^^^^^^^^^^^^^^^^^^^^^^
PermissionError: [Errno 13] Permission denied: 'tmp\\data.xlsx'
======================== content ========================: 
ABC123qwer
2024-10-20 20:32:26,252 - __main__ - ERROR - excel_index: 31 | test_index: 3 | attempt_time: 2 problem failed！
======================== wrong message ========================: 
[Errno 13] Permission denied: 'tmp\\data.xlsx'
======================== trace back ========================: 
Traceback (most recent call last):
  File "C:\Users\Admin\PycharmProjects\ByteProject\doubao\origin\v2\parallel\parallel_test.py", line 162, in request
    write_excel(excel_content)
  File "C:\Users\Admin\PycharmProjects\ByteProject\doubao\origin\v2\parallel\parallel_test.py", line 265, in write_excel
    CONSTANTS.excel_info["workbook"].save(CONSTANTS.excel_info["excel_path"])
  File "C:\Users\Admin\PycharmProjects\ByteProject\venv\Lib\site-packages\openpyxl\workbook\workbook.py", line 386, in save
    save_workbook(self, filename)
  File "C:\Users\Admin\PycharmProjects\ByteProject\venv\Lib\site-packages\openpyxl\writer\excel.py", line 291, in save_workbook
    archive = ZipFile(filename, 'w', ZIP_DEFLATED, allowZip64=True)
              ^^^^^^^^^^^^^^^^^^^^^^^^^^^^^^^^^^^^^^^^^^^^^^^^^^^^^
  File "C:\Program Files\WindowsApps\PythonSoftwareFoundation.Python.3.12_3.12.2032.0_x64__qbz5n2kfra8p0\Lib\zipfile\__init__.py", line 1331, in __init__
    self.fp = io.open(file, filemode)
              ^^^^^^^^^^^^^^^^^^^^^^^
PermissionError: [Errno 13] Permission denied: 'tmp\\data.xlsx'
======================== content ========================: 
ABC123qwertyuiopas
2024-10-20 20:32:26,408 - __main__ - ERROR - excel_index: 36 | test_index: 3 | attempt_time: 2 problem failed！
======================== wrong message ========================: 
[Errno 13] Permission denied: 'tmp\\data.xlsx'
======================== trace back ========================: 
Traceback (most recent call last):
  File "C:\Users\Admin\PycharmProjects\ByteProject\doubao\origin\v2\parallel\parallel_test.py", line 162, in request
    write_excel(excel_content)
  File "C:\Users\Admin\PycharmProjects\ByteProject\doubao\origin\v2\parallel\parallel_test.py", line 265, in write_excel
    CONSTANTS.excel_info["workbook"].save(CONSTANTS.excel_info["excel_path"])
  File "C:\Users\Admin\PycharmProjects\ByteProject\venv\Lib\site-packages\openpyxl\workbook\workbook.py", line 386, in save
    save_workbook(self, filename)
  File "C:\Users\Admin\PycharmProjects\ByteProject\venv\Lib\site-packages\openpyxl\writer\excel.py", line 291, in save_workbook
    archive = ZipFile(filename, 'w', ZIP_DEFLATED, allowZip64=True)
              ^^^^^^^^^^^^^^^^^^^^^^^^^^^^^^^^^^^^^^^^^^^^^^^^^^^^^
  File "C:\Program Files\WindowsApps\PythonSoftwareFoundation.Python.3.12_3.12.2032.0_x64__qbz5n2kfra8p0\Lib\zipfile\__init__.py", line 1331, in __init__
    self.fp = io.open(file, filemode)
              ^^^^^^^^^^^^^^^^^^^^^^^
PermissionError: [Errno 13] Permission denied: 'tmp\\data.xlsx'
======================== content ========================: 
ABC123qwertyuiopas
2024-10-20 20:32:27,782 - __main__ - ERROR - excel_index: 18 | test_index: 1 | attempt_time: 2 problem failed！
======================== wrong message ========================: 
[Errno 13] Permission denied: 'tmp\\data.xlsx'
======================== trace back ========================: 
Traceback (most recent call last):
  File "C:\Users\Admin\PycharmProjects\ByteProject\doubao\origin\v2\parallel\parallel_test.py", line 162, in request
    write_excel(excel_content)
  File "C:\Users\Admin\PycharmProjects\ByteProject\doubao\origin\v2\parallel\parallel_test.py", line 265, in write_excel
    CONSTANTS.excel_info["workbook"].save(CONSTANTS.excel_info["excel_path"])
  File "C:\Users\Admin\PycharmProjects\ByteProject\venv\Lib\site-packages\openpyxl\workbook\workbook.py", line 386, in save
    save_workbook(self, filename)
  File "C:\Users\Admin\PycharmProjects\ByteProject\venv\Lib\site-packages\openpyxl\writer\excel.py", line 291, in save_workbook
    archive = ZipFile(filename, 'w', ZIP_DEFLATED, allowZip64=True)
              ^^^^^^^^^^^^^^^^^^^^^^^^^^^^^^^^^^^^^^^^^^^^^^^^^^^^^
  File "C:\Program Files\WindowsApps\PythonSoftwareFoundation.Python.3.12_3.12.2032.0_x64__qbz5n2kfra8p0\Lib\zipfile\__init__.py", line 1331, in __init__
    self.fp = io.open(file, filemode)
              ^^^^^^^^^^^^^^^^^^^^^^^
PermissionError: [Errno 13] Permission denied: 'tmp\\data.xlsx'
======================== content ========================: 
ABC123qwer
2024-10-20 20:32:27,947 - __main__ - ERROR - excel_index: 12 | test_index: 1 | attempt_time: 2 problem failed！
======================== wrong message ========================: 
[Errno 13] Permission denied: 'tmp\\data.xlsx'
======================== trace back ========================: 
Traceback (most recent call last):
  File "C:\Users\Admin\PycharmProjects\ByteProject\doubao\origin\v2\parallel\parallel_test.py", line 162, in request
    write_excel(excel_content)
  File "C:\Users\Admin\PycharmProjects\ByteProject\doubao\origin\v2\parallel\parallel_test.py", line 265, in write_excel
    CONSTANTS.excel_info["workbook"].save(CONSTANTS.excel_info["excel_path"])
  File "C:\Users\Admin\PycharmProjects\ByteProject\venv\Lib\site-packages\openpyxl\workbook\workbook.py", line 386, in save
    save_workbook(self, filename)
  File "C:\Users\Admin\PycharmProjects\ByteProject\venv\Lib\site-packages\openpyxl\writer\excel.py", line 291, in save_workbook
    archive = ZipFile(filename, 'w', ZIP_DEFLATED, allowZip64=True)
              ^^^^^^^^^^^^^^^^^^^^^^^^^^^^^^^^^^^^^^^^^^^^^^^^^^^^^
  File "C:\Program Files\WindowsApps\PythonSoftwareFoundation.Python.3.12_3.12.2032.0_x64__qbz5n2kfra8p0\Lib\zipfile\__init__.py", line 1331, in __init__
    self.fp = io.open(file, filemode)
              ^^^^^^^^^^^^^^^^^^^^^^^
PermissionError: [Errno 13] Permission denied: 'tmp\\data.xlsx'
======================== content ========================: 
ABC123qwer
2024-10-20 20:32:28,726 - __main__ - ERROR - excel_index: 27 | test_index: 2 | attempt_time: 2 problem failed！
======================== wrong message ========================: 
[Errno 13] Permission denied: 'tmp\\data.xlsx'
======================== trace back ========================: 
Traceback (most recent call last):
  File "C:\Users\Admin\PycharmProjects\ByteProject\doubao\origin\v2\parallel\parallel_test.py", line 162, in request
    write_excel(excel_content)
  File "C:\Users\Admin\PycharmProjects\ByteProject\doubao\origin\v2\parallel\parallel_test.py", line 265, in write_excel
    CONSTANTS.excel_info["workbook"].save(CONSTANTS.excel_info["excel_path"])
  File "C:\Users\Admin\PycharmProjects\ByteProject\venv\Lib\site-packages\openpyxl\workbook\workbook.py", line 386, in save
    save_workbook(self, filename)
  File "C:\Users\Admin\PycharmProjects\ByteProject\venv\Lib\site-packages\openpyxl\writer\excel.py", line 291, in save_workbook
    archive = ZipFile(filename, 'w', ZIP_DEFLATED, allowZip64=True)
              ^^^^^^^^^^^^^^^^^^^^^^^^^^^^^^^^^^^^^^^^^^^^^^^^^^^^^
  File "C:\Program Files\WindowsApps\PythonSoftwareFoundation.Python.3.12_3.12.2032.0_x64__qbz5n2kfra8p0\Lib\zipfile\__init__.py", line 1331, in __init__
    self.fp = io.open(file, filemode)
              ^^^^^^^^^^^^^^^^^^^^^^^
PermissionError: [Errno 13] Permission denied: 'tmp\\data.xlsx'
======================== content ========================: 
ABC123qwertyui
2024-10-20 20:32:28,761 - volcenginesdkarkruntime._base_client - INFO - Retrying request to /chat/completions in 0.838125 seconds
2024-10-20 20:32:28,762 - volcenginesdkarkruntime._base_client - INFO - Retrying request to /chat/completions in 0.770797 seconds
2024-10-20 20:32:28,764 - volcenginesdkarkruntime._base_client - INFO - Retrying request to /chat/completions in 0.795442 seconds
2024-10-20 20:32:28,766 - volcenginesdkarkruntime._base_client - INFO - Retrying request to /chat/completions in 0.823796 seconds
2024-10-20 20:32:28,768 - volcenginesdkarkruntime._base_client - INFO - Retrying request to /chat/completions in 0.770361 seconds
2024-10-20 20:32:28,771 - volcenginesdkarkruntime._base_client - INFO - Retrying request to /chat/completions in 0.944760 seconds
2024-10-20 20:32:28,773 - volcenginesdkarkruntime._base_client - INFO - Retrying request to /chat/completions in 0.982534 seconds
2024-10-20 20:32:28,775 - volcenginesdkarkruntime._base_client - INFO - Retrying request to /chat/completions in 0.971620 seconds
2024-10-20 20:32:28,778 - volcenginesdkarkruntime._base_client - INFO - Retrying request to /chat/completions in 0.767125 seconds
2024-10-20 20:32:28,780 - volcenginesdkarkruntime._base_client - INFO - Retrying request to /chat/completions in 0.898868 seconds
2024-10-20 20:32:28,782 - volcenginesdkarkruntime._base_client - INFO - Retrying request to /chat/completions in 0.840881 seconds
2024-10-20 20:32:28,784 - volcenginesdkarkruntime._base_client - INFO - Retrying request to /chat/completions in 0.988682 seconds
2024-10-20 20:32:28,787 - volcenginesdkarkruntime._base_client - INFO - Retrying request to /chat/completions in 0.963051 seconds
2024-10-20 20:32:28,788 - volcenginesdkarkruntime._base_client - INFO - Retrying request to /chat/completions in 0.801383 seconds
2024-10-20 20:32:28,790 - volcenginesdkarkruntime._base_client - INFO - Retrying request to /chat/completions in 0.908148 seconds
2024-10-20 20:32:28,792 - volcenginesdkarkruntime._base_client - INFO - Retrying request to /chat/completions in 0.838113 seconds
2024-10-20 20:32:28,794 - volcenginesdkarkruntime._base_client - INFO - Retrying request to /chat/completions in 0.986261 seconds
2024-10-20 20:32:28,795 - volcenginesdkarkruntime._base_client - INFO - Retrying request to /chat/completions in 0.958107 seconds
2024-10-20 20:32:28,796 - volcenginesdkarkruntime._base_client - INFO - Retrying request to /chat/completions in 0.784022 seconds
2024-10-20 20:32:28,797 - volcenginesdkarkruntime._base_client - INFO - Retrying request to /chat/completions in 0.853241 seconds
2024-10-20 20:32:28,798 - volcenginesdkarkruntime._base_client - INFO - Retrying request to /chat/completions in 0.840245 seconds
2024-10-20 20:32:28,799 - volcenginesdkarkruntime._base_client - INFO - Retrying request to /chat/completions in 0.937508 seconds
2024-10-20 20:32:28,800 - volcenginesdkarkruntime._base_client - INFO - Retrying request to /chat/completions in 0.906062 seconds
2024-10-20 20:32:28,801 - volcenginesdkarkruntime._base_client - INFO - Retrying request to /chat/completions in 0.995727 seconds
2024-10-20 20:32:28,802 - volcenginesdkarkruntime._base_client - INFO - Retrying request to /chat/completions in 0.983197 seconds
2024-10-20 20:32:28,803 - volcenginesdkarkruntime._base_client - INFO - Retrying request to /chat/completions in 0.759872 seconds
2024-10-20 20:32:28,804 - volcenginesdkarkruntime._base_client - INFO - Retrying request to /chat/completions in 0.980876 seconds
2024-10-20 20:32:28,804 - volcenginesdkarkruntime._base_client - INFO - Retrying request to /chat/completions in 0.778749 seconds
2024-10-20 20:32:28,806 - volcenginesdkarkruntime._base_client - INFO - Retrying request to /chat/completions in 0.964694 seconds
2024-10-20 20:32:29,339 - __main__ - ERROR - excel_index: 13 | test_index: 1 | attempt_time: 0 problem failed！
2024-10-20 20:32:29,347 - __main__ - ERROR - excel_index: 14 | test_index: 1 | attempt_time: 0 problem failed！
2024-10-20 20:32:29,860 - __main__ - ERROR - excel_index: 28 | test_index: 8 | attempt_time: 0 problem failed！
2024-10-20 20:32:29,909 - __main__ - ERROR - excel_index: 23 | test_index: 8 | attempt_time: 0 problem failed！
2024-10-20 20:32:29,948 - __main__ - ERROR - excel_index: 1 | test_index: 0 | attempt_time: 0 problem failed！
2024-10-20 20:32:29,959 - __main__ - ERROR - excel_index: 22 | test_index: 8 | attempt_time: 0 problem failed！
2024-10-20 20:32:29,973 - __main__ - ERROR - excel_index: 0 | test_index: 0 | attempt_time: 0 problem failed！
2024-10-20 20:32:29,977 - __main__ - ERROR - excel_index: 37 | test_index: 9 | attempt_time: 0 problem failed！
2024-10-20 20:32:30,020 - __main__ - ERROR - excel_index: 6 | test_index: 0 | attempt_time: 0 problem failed！
2024-10-20 20:32:30,030 - __main__ - ERROR - excel_index: 4 | test_index: 0 | attempt_time: 0 problem failed！
2024-10-20 20:32:30,040 - __main__ - ERROR - excel_index: 31 | test_index: 9 | attempt_time: 0 problem failed！
2024-10-20 20:32:30,043 - __main__ - ERROR - excel_index: 7 | test_index: 0 | attempt_time: 0 problem failed！
2024-10-20 20:32:30,045 - __main__ - ERROR - excel_index: 34 | test_index: 9 | attempt_time: 0 problem failed！
2024-10-20 20:32:30,047 - __main__ - ERROR - excel_index: 3 | test_index: 0 | attempt_time: 0 problem failed！
2024-10-20 20:32:30,058 - __main__ - ERROR - excel_index: 18 | test_index: 1 | attempt_time: 0 problem failed！
2024-10-20 20:32:30,101 - __main__ - ERROR - excel_index: 32 | test_index: 9 | attempt_time: 0 problem failed！
2024-10-20 20:32:30,217 - __main__ - ERROR - excel_index: 19 | test_index: 1 | attempt_time: 0 problem failed！
2024-10-20 20:32:30,224 - __main__ - ERROR - excel_index: 2 | test_index: 0 | attempt_time: 0 problem failed！
2024-10-20 20:32:30,226 - __main__ - ERROR - excel_index: 30 | test_index: 9 | attempt_time: 0 problem failed！
2024-10-20 20:32:30,246 - __main__ - ERROR - excel_index: 16 | test_index: 1 | attempt_time: 0 problem failed！
2024-10-20 20:32:30,308 - __main__ - ERROR - excel_index: 15 | test_index: 1 | attempt_time: 0 problem failed！
2024-10-20 20:32:30,347 - __main__ - ERROR - excel_index: 12 | test_index: 1 | attempt_time: 0 problem failed！
2024-10-20 20:32:30,349 - __main__ - ERROR - excel_index: 5 | test_index: 0 | attempt_time: 0 problem failed！
2024-10-20 20:32:30,440 - __main__ - ERROR - excel_index: 8 | test_index: 0 | attempt_time: 0 problem failed！
2024-10-20 20:32:30,445 - __main__ - ERROR - excel_index: 10 | test_index: 1 | attempt_time: 0 problem failed！
2024-10-20 20:32:30,461 - __main__ - ERROR - excel_index: 17 | test_index: 1 | attempt_time: 0 problem failed！
2024-10-20 20:32:30,487 - __main__ - ERROR - excel_index: 11 | test_index: 1 | attempt_time: 0 problem failed！
2024-10-20 20:32:30,584 - __main__ - ERROR - excel_index: 20 | test_index: 8 | attempt_time: 0 problem failed！
2024-10-20 20:32:30,810 - __main__ - ERROR - excel_index: 36 | test_index: 9 | attempt_time: 0 problem failed！
2024-10-20 20:32:30,851 - __main__ - ERROR - excel_index: 26 | test_index: 8 | attempt_time: 0 problem failed！
2024-10-20 20:32:30,858 - __main__ - ERROR - excel_index: 24 | test_index: 8 | attempt_time: 0 problem failed！
2024-10-20 20:32:30,866 - __main__ - ERROR - excel_index: 25 | test_index: 8 | attempt_time: 0 problem failed！
2024-10-20 20:32:30,882 - __main__ - ERROR - excel_index: 29 | test_index: 8 | attempt_time: 0 problem failed！
2024-10-20 20:32:30,936 - __main__ - ERROR - excel_index: 21 | test_index: 8 | attempt_time: 0 problem failed！
2024-10-20 20:32:31,080 - __main__ - ERROR - excel_index: 27 | test_index: 8 | attempt_time: 0 problem failed！
2024-10-20 20:32:31,264 - __main__ - ERROR - excel_index: 35 | test_index: 9 | attempt_time: 0 problem failed！
2024-10-20 20:32:31,352 - __main__ - ERROR - excel_index: 33 | test_index: 9 | attempt_time: 0 problem failed！
2024-10-20 20:32:31,536 - __main__ - ERROR - excel_index: 39 | test_index: 9 | attempt_time: 0 problem failed！
2024-10-20 20:32:31,997 - __main__ - ERROR - excel_index: 38 | test_index: 9 | attempt_time: 0 problem failed！
2024-10-20 20:32:33,507 - __main__ - ERROR - excel_index: 9 | test_index: 0 | attempt_time: 0 problem failed！
2024-10-20 20:32:34,793 - __main__ - ERROR - excel_index: 13 | test_index: 1 | attempt_time: 1 problem failed！
2024-10-20 20:32:34,965 - __main__ - ERROR - excel_index: 14 | test_index: 1 | attempt_time: 1 problem failed！
2024-10-20 20:32:35,348 - __main__ - ERROR - excel_index: 1 | test_index: 0 | attempt_time: 1 problem failed！
2024-10-20 20:32:35,393 - __main__ - ERROR - excel_index: 0 | test_index: 0 | attempt_time: 1 problem failed！
2024-10-20 20:32:35,439 - __main__ - ERROR - excel_index: 7 | test_index: 0 | attempt_time: 1 problem failed！
2024-10-20 20:32:35,496 - __main__ - ERROR - excel_index: 6 | test_index: 0 | attempt_time: 1 problem failed！
2024-10-20 20:32:35,539 - __main__ - ERROR - excel_index: 4 | test_index: 0 | attempt_time: 1 problem failed！
2024-10-20 20:32:35,626 - __main__ - ERROR - excel_index: 2 | test_index: 0 | attempt_time: 1 problem failed！
2024-10-20 20:32:35,631 - __main__ - ERROR - excel_index: 18 | test_index: 1 | attempt_time: 1 problem failed！
2024-10-20 20:32:35,633 - __main__ - ERROR - excel_index: 3 | test_index: 0 | attempt_time: 1 problem failed！
2024-10-20 20:32:35,751 - __main__ - ERROR - excel_index: 15 | test_index: 1 | attempt_time: 1 problem failed！
2024-10-20 20:32:35,753 - __main__ - ERROR - excel_index: 19 | test_index: 1 | attempt_time: 1 problem failed！
2024-10-20 20:32:35,859 - __main__ - ERROR - excel_index: 5 | test_index: 0 | attempt_time: 1 problem failed！
2024-10-20 20:32:35,865 - __main__ - ERROR - excel_index: 10 | test_index: 1 | attempt_time: 1 problem failed！
2024-10-20 20:32:35,932 - __main__ - ERROR - excel_index: 8 | test_index: 0 | attempt_time: 1 problem failed！
2024-10-20 20:32:35,935 - __main__ - ERROR - excel_index: 17 | test_index: 1 | attempt_time: 1 problem failed！
2024-10-20 20:32:35,939 - __main__ - ERROR - excel_index: 12 | test_index: 1 | attempt_time: 1 problem failed！
2024-10-20 20:32:35,999 - __main__ - ERROR - excel_index: 11 | test_index: 1 | attempt_time: 1 problem failed！
2024-10-20 20:32:36,098 - __main__ - ERROR - excel_index: 23 | test_index: 8 | attempt_time: 1 problem failed！
2024-10-20 20:32:36,100 - __main__ - ERROR - excel_index: 22 | test_index: 8 | attempt_time: 1 problem failed！
2024-10-20 20:32:36,228 - __main__ - ERROR - excel_index: 37 | test_index: 9 | attempt_time: 1 problem failed！
2024-10-20 20:32:36,298 - __main__ - ERROR - excel_index: 30 | test_index: 9 | attempt_time: 1 problem failed！
2024-10-20 20:32:36,301 - __main__ - ERROR - excel_index: 32 | test_index: 9 | attempt_time: 1 problem failed！
2024-10-20 20:32:36,455 - __main__ - ERROR - excel_index: 34 | test_index: 9 | attempt_time: 1 problem failed！
2024-10-20 20:32:36,527 - __main__ - ERROR - excel_index: 31 | test_index: 9 | attempt_time: 1 problem failed！
2024-10-20 20:32:36,575 - __main__ - ERROR - excel_index: 16 | test_index: 1 | attempt_time: 1 problem failed！
2024-10-20 20:32:36,624 - __main__ - ERROR - excel_index: 20 | test_index: 8 | attempt_time: 1 problem failed！
2024-10-20 20:32:37,424 - __main__ - ERROR - excel_index: 33 | test_index: 9 | attempt_time: 1 problem failed！
2024-10-20 20:32:37,462 - __main__ - ERROR - excel_index: 36 | test_index: 9 | attempt_time: 1 problem failed！
2024-10-20 20:32:37,473 - __main__ - ERROR - excel_index: 25 | test_index: 8 | attempt_time: 1 problem failed！
2024-10-20 20:32:37,494 - __main__ - ERROR - excel_index: 29 | test_index: 8 | attempt_time: 1 problem failed！
2024-10-20 20:32:37,539 - __main__ - ERROR - excel_index: 27 | test_index: 8 | attempt_time: 1 problem failed！
2024-10-20 20:34:10,870 - __main__ - INFO - 开始计算
2024-10-20 20:34:11,357 - __main__ - ERROR - excel_index: 7 | test_index: 0 | attempt_time: 0 problem failed！
2024-10-20 20:34:11,379 - __main__ - ERROR - excel_index: 9 | test_index: 0 | attempt_time: 0 problem failed！
2024-10-20 20:34:11,383 - __main__ - ERROR - excel_index: 3 | test_index: 0 | attempt_time: 0 problem failed！
2024-10-20 20:34:11,403 - __main__ - ERROR - excel_index: 1 | test_index: 0 | attempt_time: 0 problem failed！
2024-10-20 20:34:11,408 - __main__ - ERROR - excel_index: 6 | test_index: 0 | attempt_time: 0 problem failed！
2024-10-20 20:34:11,416 - __main__ - ERROR - excel_index: 4 | test_index: 0 | attempt_time: 0 problem failed！
2024-10-20 20:34:11,418 - __main__ - ERROR - excel_index: 0 | test_index: 0 | attempt_time: 0 problem failed！
2024-10-20 20:34:11,422 - __main__ - ERROR - excel_index: 5 | test_index: 0 | attempt_time: 0 problem failed！
2024-10-20 20:34:11,430 - __main__ - ERROR - excel_index: 2 | test_index: 0 | attempt_time: 0 problem failed！
2024-10-20 20:34:11,473 - __main__ - ERROR - excel_index: 8 | test_index: 0 | attempt_time: 0 problem failed！
2024-10-20 20:34:11,478 - __main__ - ERROR - excel_index: 13 | test_index: 1 | attempt_time: 0 problem failed！
2024-10-20 20:34:11,484 - __main__ - ERROR - excel_index: 15 | test_index: 1 | attempt_time: 0 problem failed！
2024-10-20 20:34:11,506 - __main__ - ERROR - excel_index: 12 | test_index: 1 | attempt_time: 0 problem failed！
2024-10-20 20:34:11,508 - __main__ - ERROR - excel_index: 14 | test_index: 1 | attempt_time: 0 problem failed！
2024-10-20 20:34:11,528 - __main__ - ERROR - excel_index: 11 | test_index: 1 | attempt_time: 0 problem failed！
2024-10-20 20:34:11,568 - __main__ - ERROR - excel_index: 19 | test_index: 1 | attempt_time: 0 problem failed！
2024-10-20 20:34:11,585 - __main__ - ERROR - excel_index: 18 | test_index: 1 | attempt_time: 0 problem failed！
2024-10-20 20:34:11,617 - __main__ - ERROR - excel_index: 10 | test_index: 1 | attempt_time: 0 problem failed！
2024-10-20 20:34:11,621 - __main__ - ERROR - excel_index: 16 | test_index: 1 | attempt_time: 0 problem failed！
2024-10-20 20:34:11,627 - __main__ - ERROR - excel_index: 21 | test_index: 2 | attempt_time: 0 problem failed！
2024-10-20 20:34:11,628 - __main__ - ERROR - excel_index: 23 | test_index: 2 | attempt_time: 0 problem failed！
2024-10-20 20:34:11,630 - __main__ - ERROR - excel_index: 22 | test_index: 2 | attempt_time: 0 problem failed！
2024-10-20 20:34:11,643 - __main__ - ERROR - excel_index: 26 | test_index: 2 | attempt_time: 0 problem failed！
2024-10-20 20:34:11,649 - __main__ - ERROR - excel_index: 24 | test_index: 2 | attempt_time: 0 problem failed！
2024-10-20 20:34:11,652 - __main__ - ERROR - excel_index: 20 | test_index: 2 | attempt_time: 0 problem failed！
2024-10-20 20:34:11,684 - __main__ - ERROR - excel_index: 28 | test_index: 2 | attempt_time: 0 problem failed！
2024-10-20 20:34:11,687 - __main__ - ERROR - excel_index: 17 | test_index: 1 | attempt_time: 0 problem failed！
2024-10-20 20:34:11,688 - __main__ - ERROR - excel_index: 29 | test_index: 2 | attempt_time: 0 problem failed！
2024-10-20 20:34:11,709 - __main__ - ERROR - excel_index: 27 | test_index: 2 | attempt_time: 0 problem failed！
2024-10-20 20:34:11,711 - __main__ - ERROR - excel_index: 30 | test_index: 3 | attempt_time: 0 problem failed！
2024-10-20 20:34:11,722 - __main__ - ERROR - excel_index: 37 | test_index: 3 | attempt_time: 0 problem failed！
2024-10-20 20:34:11,729 - __main__ - ERROR - excel_index: 38 | test_index: 3 | attempt_time: 0 problem failed！
2024-10-20 20:34:11,739 - __main__ - ERROR - excel_index: 44 | test_index: 4 | attempt_time: 0 problem failed！
2024-10-20 20:34:11,742 - __main__ - ERROR - excel_index: 39 | test_index: 3 | attempt_time: 0 problem failed！
2024-10-20 20:34:11,765 - __main__ - ERROR - excel_index: 43 | test_index: 4 | attempt_time: 0 problem failed！
2024-10-20 20:34:11,769 - __main__ - ERROR - excel_index: 36 | test_index: 3 | attempt_time: 0 problem failed！
2024-10-20 20:34:11,773 - __main__ - ERROR - excel_index: 31 | test_index: 3 | attempt_time: 0 problem failed！
2024-10-20 20:34:11,788 - __main__ - ERROR - excel_index: 42 | test_index: 4 | attempt_time: 0 problem failed！
2024-10-20 20:34:11,792 - __main__ - ERROR - excel_index: 48 | test_index: 4 | attempt_time: 0 problem failed！
2024-10-20 20:34:11,801 - __main__ - ERROR - excel_index: 35 | test_index: 3 | attempt_time: 0 problem failed！
2024-10-20 20:34:11,808 - __main__ - ERROR - excel_index: 34 | test_index: 3 | attempt_time: 0 problem failed！
2024-10-20 20:34:11,812 - __main__ - ERROR - excel_index: 49 | test_index: 4 | attempt_time: 0 problem failed！
2024-10-20 20:34:11,841 - __main__ - ERROR - excel_index: 45 | test_index: 4 | attempt_time: 0 problem failed！
2024-10-20 20:34:11,850 - __main__ - ERROR - excel_index: 46 | test_index: 4 | attempt_time: 0 problem failed！
2024-10-20 20:34:11,856 - __main__ - ERROR - excel_index: 32 | test_index: 3 | attempt_time: 0 problem failed！
2024-10-20 20:34:11,859 - __main__ - ERROR - excel_index: 41 | test_index: 4 | attempt_time: 0 problem failed！
2024-10-20 20:34:11,977 - __main__ - ERROR - excel_index: 25 | test_index: 2 | attempt_time: 0 problem failed！
2024-10-20 20:34:12,213 - __main__ - ERROR - excel_index: 47 | test_index: 4 | attempt_time: 0 problem failed！
2024-10-20 20:34:12,907 - __main__ - ERROR - excel_index: 33 | test_index: 3 | attempt_time: 0 problem failed！
2024-10-20 20:34:13,638 - __main__ - ERROR - excel_index: 40 | test_index: 4 | attempt_time: 0 problem failed！
2024-10-20 20:34:16,769 - __main__ - ERROR - excel_index: 7 | test_index: 0 | attempt_time: 1 problem failed！
2024-10-20 20:34:16,779 - __main__ - ERROR - excel_index: 9 | test_index: 0 | attempt_time: 1 problem failed！
2024-10-20 20:34:16,792 - __main__ - ERROR - excel_index: 4 | test_index: 0 | attempt_time: 1 problem failed！
2024-10-20 20:34:16,798 - __main__ - ERROR - excel_index: 6 | test_index: 0 | attempt_time: 1 problem failed！
2024-10-20 20:34:16,828 - __main__ - ERROR - excel_index: 0 | test_index: 0 | attempt_time: 1 problem failed！
2024-10-20 20:34:16,830 - __main__ - ERROR - excel_index: 2 | test_index: 0 | attempt_time: 1 problem failed！
2024-10-20 20:34:16,848 - __main__ - ERROR - excel_index: 3 | test_index: 0 | attempt_time: 1 problem failed！
2024-10-20 20:34:16,903 - __main__ - ERROR - excel_index: 8 | test_index: 0 | attempt_time: 1 problem failed！
2024-10-20 20:34:16,910 - __main__ - ERROR - excel_index: 1 | test_index: 0 | attempt_time: 1 problem failed！
2024-10-20 20:34:17,022 - __main__ - ERROR - excel_index: 12 | test_index: 1 | attempt_time: 1 problem failed！
2024-10-20 20:34:17,030 - __main__ - ERROR - excel_index: 15 | test_index: 1 | attempt_time: 1 problem failed！
2024-10-20 20:34:17,035 - __main__ - ERROR - excel_index: 13 | test_index: 1 | attempt_time: 1 problem failed！
2024-10-20 20:34:17,039 - __main__ - ERROR - excel_index: 14 | test_index: 1 | attempt_time: 1 problem failed！
2024-10-20 20:34:17,109 - __main__ - ERROR - excel_index: 18 | test_index: 1 | attempt_time: 1 problem failed！
2024-10-20 20:34:17,174 - __main__ - ERROR - excel_index: 11 | test_index: 1 | attempt_time: 1 problem failed！
2024-10-20 20:34:17,196 - __main__ - ERROR - excel_index: 10 | test_index: 1 | attempt_time: 1 problem failed！
2024-10-20 20:34:17,228 - __main__ - ERROR - excel_index: 19 | test_index: 1 | attempt_time: 1 problem failed！
2024-10-20 20:34:17,282 - __main__ - ERROR - excel_index: 26 | test_index: 2 | attempt_time: 1 problem failed！
2024-10-20 20:34:17,284 - __main__ - ERROR - excel_index: 16 | test_index: 1 | attempt_time: 1 problem failed！
2024-10-20 20:34:17,303 - __main__ - ERROR - excel_index: 17 | test_index: 1 | attempt_time: 1 problem failed！
2024-10-20 20:34:17,365 - __main__ - ERROR - excel_index: 23 | test_index: 2 | attempt_time: 1 problem failed！
2024-10-20 20:34:17,377 - __main__ - ERROR - excel_index: 21 | test_index: 2 | attempt_time: 1 problem failed！
2024-10-20 20:34:17,387 - __main__ - ERROR - excel_index: 24 | test_index: 2 | attempt_time: 1 problem failed！
2024-10-20 20:34:17,398 - __main__ - ERROR - excel_index: 22 | test_index: 2 | attempt_time: 1 problem failed！
2024-10-20 20:34:17,413 - __main__ - ERROR - excel_index: 31 | test_index: 3 | attempt_time: 1 problem failed！
2024-10-20 20:34:17,432 - __main__ - ERROR - excel_index: 36 | test_index: 3 | attempt_time: 1 problem failed！
2024-10-20 20:34:17,453 - __main__ - ERROR - excel_index: 20 | test_index: 2 | attempt_time: 1 problem failed！
2024-10-20 20:34:17,479 - __main__ - ERROR - excel_index: 42 | test_index: 4 | attempt_time: 1 problem failed！
2024-10-20 20:34:17,511 - __main__ - ERROR - excel_index: 32 | test_index: 3 | attempt_time: 1 problem failed！
2024-10-20 20:34:17,543 - __main__ - ERROR - excel_index: 29 | test_index: 2 | attempt_time: 1 problem failed！
2024-10-20 20:34:17,547 - __main__ - ERROR - excel_index: 30 | test_index: 3 | attempt_time: 1 problem failed！
2024-10-20 20:34:17,549 - __main__ - ERROR - excel_index: 45 | test_index: 4 | attempt_time: 1 problem failed！
2024-10-20 20:34:17,550 - __main__ - ERROR - excel_index: 38 | test_index: 3 | attempt_time: 1 problem failed！
2024-10-20 20:34:17,552 - __main__ - ERROR - excel_index: 27 | test_index: 2 | attempt_time: 1 problem failed！
2024-10-20 20:34:17,553 - __main__ - ERROR - excel_index: 49 | test_index: 4 | attempt_time: 1 problem failed！
2024-10-20 20:34:17,566 - __main__ - ERROR - excel_index: 35 | test_index: 3 | attempt_time: 1 problem failed！
2024-10-20 20:34:17,596 - __main__ - ERROR - excel_index: 37 | test_index: 3 | attempt_time: 1 problem failed！
2024-10-20 20:34:17,598 - __main__ - ERROR - excel_index: 48 | test_index: 4 | attempt_time: 1 problem failed！
2024-10-20 20:34:17,600 - __main__ - ERROR - excel_index: 43 | test_index: 4 | attempt_time: 1 problem failed！
2024-10-20 20:34:17,603 - __main__ - ERROR - excel_index: 25 | test_index: 2 | attempt_time: 1 problem failed！
2024-10-20 20:34:17,604 - __main__ - ERROR - excel_index: 34 | test_index: 3 | attempt_time: 1 problem failed！
2024-10-20 20:34:17,617 - __main__ - ERROR - excel_index: 46 | test_index: 4 | attempt_time: 1 problem failed！
2024-10-20 20:34:17,649 - __main__ - ERROR - excel_index: 39 | test_index: 3 | attempt_time: 1 problem failed！
2024-10-20 20:34:17,672 - __main__ - ERROR - excel_index: 44 | test_index: 4 | attempt_time: 1 problem failed！
2024-10-20 20:34:17,687 - __main__ - ERROR - excel_index: 41 | test_index: 4 | attempt_time: 1 problem failed！
2024-10-20 20:34:17,939 - __main__ - ERROR - excel_index: 47 | test_index: 4 | attempt_time: 1 problem failed！
2024-10-20 20:34:18,645 - __main__ - ERROR - excel_index: 33 | test_index: 3 | attempt_time: 1 problem failed！
